<mujoco model="humanoid">
  <compiler angle="degree" inertiafromgeom="true" coordinate="global"/>
  <include file="./common/materials.xml"/>
  <visual>
    <headlight ambient=".4 .4 .4" diffuse=".8 .8 .8" specular="0.1 0.1 0.1"/>
    <map znear=".01"/>
    <quality shadowsize="2048"/>
  </visual>
  <default>
    <joint damping="0.0" armature="0.01" stiffness="0.0" limited="true"/>
    <geom conaffinity="7" condim="1" contype="7" margin="0.001" material="self" rgba="0.8 0.6 .4 1"/>
  </default>
  <statistic extent="3" center="0 0 1"/>
  <option timestep="0.00222222222"/>
  <asset>
    <texture type="skybox" file="./common/sky1.png" gridsize="3 4" gridlayout=".U..LFRB.D.." width="8192" height="8192"/>
    <texture builtin="flat" height="1278" mark="cross" markrgb="1 1 1" name="texgeom" random="0.01" rgb1=".8 .6 .4" rgb2=".8 .6 .4" type="cube" width="127"/>
  </asset>
  <worldbody>
    <light cutoff="100" diffuse="1 1 1" dir="-0 0 -1.3" directional="true" exponent="1" pos="0 0 1.3" specular=".1 .1 .1"/>
    <geom condim="3" friction="1. .1 .1" material="grid" name="floor" pos="0 0 0" rgba=".8 .9 .8 1" size="100 100 .2" type="plane"/>
    <body name="Hips" pos="0.0000 0.0000 1.0000" user="0.0000 0.0003 1.0000">
      <joint name="Hips" pos="0.0000 0.0000 1.0000" limited="false" type="free" armature="0" damping="0" stiffness="0"/>
      <geom size="0.0300" type="sphere" pos="0.0000 0.0000 1.0000"/>
      <body name="RightUpLeg" pos="-0.1272 0.0000 1.0000" user="-0.1272 -0.4343 1.0000">
        <joint name="RightUpLeg_z" type="hinge" pos="-0.1272 0.0000 1.0000" axis="0.0000 0.0000 1.0000" range="-180.0000 180.0000"/>
        <joint name="RightUpLeg_x" type="hinge" pos="-0.1272 0.0000 1.0000" axis="1.0000 0.0000 0.0000" range="-180.0000 180.0000"/>
        <joint name="RightUpLeg_y" type="hinge" pos="-0.1272 0.0000 1.0000" axis="0.0000 1.0000 0.0000" range="-180.0000 180.0000"/>
        <geom size="0.0300" type="capsule" fromto="-0.1272 -0.0200 1.0000 -0.1272 -0.4143 1.0000"/>
        <body name="RightLeg" pos="-0.1272 -0.4343 1.0000" user="-0.1272 -0.8831 1.0000">
          <joint name="RightLeg_x" type="hinge" pos="-0.1272 -0.4343 1.0000" axis="1.0000 0.0000 0.0000" range="-180.0000 180.0000"/>
          <geom size="0.0300" type="capsule" fromto="-0.1272 -0.4543 1.0000 -0.1272 -0.8631 1.0000"/>
          <body name="RightFoot" pos="-0.1272 -0.8831 1.0000" user="-0.1272 -0.8831 1.1515">
            <joint name="RightFoot_z" type="hinge" pos="-0.1272 -0.8831 1.0000" axis="0.0000 0.0000 1.0000" range="-180.0000 180.0000"/>
            <joint name="RightFoot_x" type="hinge" pos="-0.1272 -0.8831 1.0000" axis="1.0000 0.0000 0.0000" range="-180.0000 180.0000"/>
            <joint name="RightFoot_y" type="hinge" pos="-0.1272 -0.8831 1.0000" axis="0.0000 1.0000 0.0000" range="-180.0000 180.0000"/>
            <geom size="0.0300" type="capsule" fromto="-0.1272 -0.8831 1.0200 -0.1272 -0.8831 1.1315"/>
          </body>
        </body>
      </body>
      <body name="LeftUpLeg" pos="0.1272 0.0000 1.0000" user="0.1272 -0.4343 1.0000">
        <joint name="LeftUpLeg_z" type="hinge" pos="0.1272 0.0000 1.0000" axis="0.0000 0.0000 1.0000" range="-180.0000 180.0000"/>
        <joint name="LeftUpLeg_x" type="hinge" pos="0.1272 0.0000 1.0000" axis="1.0000 0.0000 0.0000" range="-180.0000 180.0000"/>
        <joint name="LeftUpLeg_y" type="hinge" pos="0.1272 0.0000 1.0000" axis="0.0000 1.0000 0.0000" range="-180.0000 180.0000"/>
        <geom size="0.0300" type="capsule" fromto="0.1272 -0.0200 1.0000 0.1272 -0.4143 1.0000"/>
        <body name="LeftLeg" pos="0.1272 -0.4343 1.0000" user="0.1272 -0.8831 1.0000">
          <joint name="LeftLeg_x" type="hinge" pos="0.1272 -0.4343 1.0000" axis="1.0000 0.0000 0.0000" range="-180.0000 180.0000"/>
          <geom size="0.0300" type="capsule" fromto="0.1272 -0.4543 1.0000 0.1272 -0.8631 1.0000"/>
          <body name="LeftFoot" pos="0.1272 -0.8831 1.0000" user="0.1272 -0.8831 1.1515">
            <joint name="LeftFoot_z" type="hinge" pos="0.1272 -0.8831 1.0000" axis="0.0000 0.0000 1.0000" range="-180.0000 180.0000"/>
            <joint name="LeftFoot_x" type="hinge" pos="0.1272 -0.8831 1.0000" axis="1.0000 0.0000 0.0000" range="-180.0000 180.0000"/>
            <joint name="LeftFoot_y" type="hinge" pos="0.1272 -0.8831 1.0000" axis="0.0000 1.0000 0.0000" range="-180.0000 180.0000"/>
            <geom size="0.0300" type="capsule" fromto="0.1272 -0.8831 1.0200 0.1272 -0.8831 1.1315"/>
          </body>
        </body>
      </body>
      <body name="Spine" pos="0.0000 0.0010 1.0000" user="0.0000 0.2469 1.0000">
        <joint name="Spine_z" type="hinge" pos="0.0000 0.0010 1.0000" axis="0.0000 0.0000 1.0000" range="-180.0000 180.0000"/>
        <joint name="Spine_x" type="hinge" pos="0.0000 0.0010 1.0000" axis="1.0000 0.0000 0.0000" range="-180.0000 180.0000"/>
        <joint name="Spine_y" type="hinge" pos="0.0000 0.0010 1.0000" axis="0.0000 1.0000 0.0000" range="-180.0000 180.0000"/>
        <geom size="0.0300" type="capsule" fromto="0.0000 0.0210 1.0000 0.0000 0.2269 1.0000"/>
        <body name="Spine1" pos="0.0000 0.2469 1.0000" user="0.0000 0.4954 1.0000">
          <joint name="Spine1_z" type="hinge" pos="0.0000 0.2469 1.0000" axis="0.0000 0.0000 1.0000" range="-180.0000 180.0000"/>
          <joint name="Spine1_x" type="hinge" pos="0.0000 0.2469 1.0000" axis="1.0000 0.0000 0.0000" range="-180.0000 180.0000"/>
          <joint name="Spine1_y" type="hinge" pos="0.0000 0.2469 1.0000" axis="0.0000 1.0000 0.0000" range="-180.0000 180.0000"/>
          <geom size="0.0300" type="capsule" fromto="0.0000 0.2669 1.0000 0.0000 0.4754 1.0000"/>
          <body name="Neck" pos="0.0000 0.4954 1.0000" user="0.0000 0.5881 1.0000">
            <joint name="Neck_z" type="hinge" pos="0.0000 0.4954 1.0000" axis="0.0000 0.0000 1.0000" range="-180.0000 180.0000"/>
            <joint name="Neck_x" type="hinge" pos="0.0000 0.4954 1.0000" axis="1.0000 0.0000 0.0000" range="-180.0000 180.0000"/>
            <joint name="Neck_y" type="hinge" pos="0.0000 0.4954 1.0000" axis="0.0000 1.0000 0.0000" range="-180.0000 180.0000"/>
            <geom size="0.0300" type="capsule" fromto="0.0000 0.5154 1.0000 0.0000 0.5681 1.0000"/>
            <body name="Head" pos="0.0000 0.5881 1.0000" user="0.0000 0.7031 1.0000">
              <joint name="Head_z" type="hinge" pos="0.0000 0.5881 1.0000" axis="0.0000 0.0000 1.0000" range="-180.0000 180.0000"/>
              <joint name="Head_x" type="hinge" pos="0.0000 0.5881 1.0000" axis="1.0000 0.0000 0.0000" range="-180.0000 180.0000"/>
              <joint name="Head_y" type="hinge" pos="0.0000 0.5881 1.0000" axis="0.0000 1.0000 0.0000" range="-180.0000 180.0000"/>
              <geom size="0.0300" type="capsule" fromto="0.0000 0.6081 1.0000 0.0000 0.6831 1.0000"/>
            </body>
          </body>
          <body name="LeftShoulder" pos="0.0000 0.4954 1.0000" user="0.0000 0.6203 1.0000">
            <joint name="LeftShoulder_z" type="hinge" pos="0.0000 0.4954 1.0000" axis="0.0000 0.0000 1.0000" range="-180.0000 180.0000"/>
            <joint name="LeftShoulder_x" type="hinge" pos="0.0000 0.4954 1.0000" axis="1.0000 0.0000 0.0000" range="-180.0000 180.0000"/>
            <joint name="LeftShoulder_y" type="hinge" pos="0.0000 0.4954 1.0000" axis="0.0000 1.0000 0.0000" range="-180.0000 180.0000"/>
            <geom size="0.0300" type="capsule" fromto="0.0000 0.5154 1.0000 0.0000 0.6003 1.0000"/>
            <body name="LeftArm" pos="0.0000 0.6203 1.0000" user="0.0000 0.8800 1.0000">
              <joint name="LeftArm_z" type="hinge" pos="0.0000 0.6203 1.0000" axis="0.0000 0.0000 1.0000" range="-180.0000 180.0000"/>
              <joint name="LeftArm_x" type="hinge" pos="0.0000 0.6203 1.0000" axis="1.0000 0.0000 0.0000" range="-180.0000 180.0000"/>
              <joint name="LeftArm_y" type="hinge" pos="0.0000 0.6203 1.0000" axis="0.0000 1.0000 0.0000" range="-180.0000 180.0000"/>
              <geom size="0.0300" type="capsule" fromto="0.0000 0.6403 1.0000 0.0000 0.8600 1.0000"/>
              <body name="LeftForeArm" pos="0.0000 0.8800 1.0000" user="0.0000 1.1256 1.0000">
                <joint name="LeftForeArm_x" type="hinge" pos="0.0000 0.8800 1.0000" axis="1.0000 0.0000 0.0000" range="-180.0000 180.0000"/>
                <geom size="0.0300" type="capsule" fromto="0.0000 0.9000 1.0000 0.0000 1.1056 1.0000"/>
                <body name="LeftHand" pos="0.0000 1.1256 1.0000" user="0.0000 1.1256 1.0000">
                  <joint name="LeftHand_z" type="hinge" pos="0.0000 1.1256 1.0000" axis="0.0000 0.0000 1.0000" range="-180.0000 180.0000"/>
                  <joint name="LeftHand_x" type="hinge" pos="0.0000 1.1256 1.0000" axis="1.0000 0.0000 0.0000" range="-180.0000 180.0000"/>
                  <joint name="LeftHand_y" type="hinge" pos="0.0000 1.1256 1.0000" axis="0.0000 1.0000 0.0000" range="-180.0000 180.0000"/>
                  <geom size="0.0300" type="capsule" fromto="0.0000 1.1256 1.0040 0.0000 1.1256 0.9960"/>
                </body>
              </body>
            </body>
          </body>
          <body name="RightShoulder" pos="0.0000 0.4954 1.0000" user="0.0000 0.6203 1.0000">
            <joint name="RightShoulder_z" type="hinge" pos="0.0000 0.4954 1.0000" axis="0.0000 0.0000 1.0000" range="-180.0000 180.0000"/>
            <joint name="RightShoulder_x" type="hinge" pos="0.0000 0.4954 1.0000" axis="1.0000 0.0000 0.0000" range="-180.0000 180.0000"/>
            <joint name="RightShoulder_y" type="hinge" pos="0.0000 0.4954 1.0000" axis="0.0000 1.0000 0.0000" range="-180.0000 180.0000"/>
            <geom size="0.0300" type="capsule" fromto="0.0000 0.5154 1.0000 0.0000 0.6003 1.0000"/>
            <body name="RightArm" pos="0.0000 0.6203 1.0000" user="0.0000 0.8800 1.0000">
              <joint name="RightArm_z" type="hinge" pos="0.0000 0.6203 1.0000" axis="0.0000 0.0000 1.0000" range="-180.0000 180.0000"/>
              <joint name="RightArm_x" type="hinge" pos="0.0000 0.6203 1.0000" axis="1.0000 0.0000 0.0000" range="-180.0000 180.0000"/>
              <joint name="RightArm_y" type="hinge" pos="0.0000 0.6203 1.0000" axis="0.0000 1.0000 0.0000" range="-180.0000 180.0000"/>
              <geom size="0.0300" type="capsule" fromto="0.0000 0.6403 1.0000 0.0000 0.8600 1.0000"/>
              <body name="RightForeArm" pos="0.0000 0.8800 1.0000" user="0.0000 1.1256 1.0000">
                <joint name="RightForeArm_x" type="hinge" pos="0.0000 0.8800 1.0000" axis="1.0000 0.0000 0.0000" range="-180.0000 180.0000"/>
                <geom size="0.0300" type="capsule" fromto="0.0000 0.9000 1.0000 0.0000 1.1056 1.0000"/>
                <body name="RightHand" pos="0.0000 1.1256 1.0000" user="0.0000 1.1256 1.0000">
                  <joint name="RightHand_z" type="hinge" pos="0.0000 1.1256 1.0000" axis="0.0000 0.0000 1.0000" range="-180.0000 180.0000"/>
                  <joint name="RightHand_x" type="hinge" pos="0.0000 1.1256 1.0000" axis="1.0000 0.0000 0.0000" range="-180.0000 180.0000"/>
                  <joint name="RightHand_y" type="hinge" pos="0.0000 1.1256 1.0000" axis="0.0000 1.0000 0.0000" range="-180.0000 180.0000"/>
                  <geom size="0.0300" type="capsule" fromto="0.0000 1.1256 1.0040 0.0000 1.1256 0.9960"/>
                </body>
              </body>
            </body>
          </body>
        </body>
      </body>
    </body>
  </worldbody>
  <actuator>
    <motor name="RightUpLeg_z" joint="RightUpLeg_z" gear="1"/>
    <motor name="RightUpLeg_x" joint="RightUpLeg_x" gear="1"/>
    <motor name="RightUpLeg_y" joint="RightUpLeg_y" gear="1"/>
    <motor name="RightLeg_x" joint="RightLeg_x" gear="1"/>
    <motor name="RightFoot_z" joint="RightFoot_z" gear="1"/>
    <motor name="RightFoot_x" joint="RightFoot_x" gear="1"/>
    <motor name="RightFoot_y" joint="RightFoot_y" gear="1"/>
    <motor name="LeftUpLeg_z" joint="LeftUpLeg_z" gear="1"/>
    <motor name="LeftUpLeg_x" joint="LeftUpLeg_x" gear="1"/>
    <motor name="LeftUpLeg_y" joint="LeftUpLeg_y" gear="1"/>
    <motor name="LeftLeg_x" joint="LeftLeg_x" gear="1"/>
    <motor name="LeftFoot_z" joint="LeftFoot_z" gear="1"/>
    <motor name="LeftFoot_x" joint="LeftFoot_x" gear="1"/>
    <motor name="LeftFoot_y" joint="LeftFoot_y" gear="1"/>
    <motor name="Spine_z" joint="Spine_z" gear="1"/>
    <motor name="Spine_x" joint="Spine_x" gear="1"/>
    <motor name="Spine_y" joint="Spine_y" gear="1"/>
    <motor name="Spine1_z" joint="Spine1_z" gear="1"/>
    <motor name="Spine1_x" joint="Spine1_x" gear="1"/>
    <motor name="Spine1_y" joint="Spine1_y" gear="1"/>
    <motor name="Neck_z" joint="Neck_z" gear="1"/>
    <motor name="Neck_x" joint="Neck_x" gear="1"/>
    <motor name="Neck_y" joint="Neck_y" gear="1"/>
    <motor name="Head_z" joint="Head_z" gear="1"/>
    <motor name="Head_x" joint="Head_x" gear="1"/>
    <motor name="Head_y" joint="Head_y" gear="1"/>
    <motor name="LeftShoulder_z" joint="LeftShoulder_z" gear="1"/>
    <motor name="LeftShoulder_x" joint="LeftShoulder_x" gear="1"/>
    <motor name="LeftShoulder_y" joint="LeftShoulder_y" gear="1"/>
    <motor name="LeftArm_z" joint="LeftArm_z" gear="1"/>
    <motor name="LeftArm_x" joint="LeftArm_x" gear="1"/>
    <motor name="LeftArm_y" joint="LeftArm_y" gear="1"/>
    <motor name="LeftForeArm_x" joint="LeftForeArm_x" gear="1"/>
    <motor name="LeftHand_z" joint="LeftHand_z" gear="1"/>
    <motor name="LeftHand_x" joint="LeftHand_x" gear="1"/>
    <motor name="LeftHand_y" joint="LeftHand_y" gear="1"/>
    <motor name="RightShoulder_z" joint="RightShoulder_z" gear="1"/>
    <motor name="RightShoulder_x" joint="RightShoulder_x" gear="1"/>
    <motor name="RightShoulder_y" joint="RightShoulder_y" gear="1"/>
    <motor name="RightArm_z" joint="RightArm_z" gear="1"/>
    <motor name="RightArm_x" joint="RightArm_x" gear="1"/>
    <motor name="RightArm_y" joint="RightArm_y" gear="1"/>
    <motor name="RightForeArm_x" joint="RightForeArm_x" gear="1"/>
    <motor name="RightHand_z" joint="RightHand_z" gear="1"/>
    <motor name="RightHand_x" joint="RightHand_x" gear="1"/>
    <motor name="RightHand_y" joint="RightHand_y" gear="1"/>
  </actuator>
</mujoco>
