<mujoco model="humanoid">
  <compiler angle="degree" inertiafromgeom="true" coordinate="global"/>
  <include file="./common/materials.xml"/>
  <visual>
    <headlight ambient=".4 .4 .4" diffuse=".8 .8 .8" specular="0.1 0.1 0.1"/>
    <map znear=".01"/>
    <quality shadowsize="2048"/>
  </visual>
  <default>
    <joint damping="0.0" armature="0.01" stiffness="0.0" limited="true"/>
    <geom conaffinity="7" condim="1" contype="7" margin="0.001" material="self" rgba="0.8 0.6 .4 1"/>
    <default class="trans">
      <geom rgba="0.8 0.6 .4 0.3"/>
    </default>
  </default>
  <statistic extent="3" center="0 0 1"/>
  <option timestep="0.00222222222">
    <flag contact="disable"/>
  </option>
  <asset>
    <texture type="skybox" file="./common/sky1.png" gridsize="3 4" gridlayout=".U..LFRB.D.." width="8192" height="8192"/>
    <texture builtin="flat" height="1278" mark="cross" markrgb="1 1 1" name="texgeom" random="0.01" rgb1=".8 .6 .4" rgb2=".8 .6 .4" type="cube" width="127"/>
  </asset>
  <worldbody>
    <light cutoff="100" diffuse="1 1 1" dir="-0 0 -1.3" directional="true" exponent="1" pos="0 0 1.3" specular=".1 .1 .1"/>
    <geom condim="3" friction="1. .1 .1" material="grid" name="floor" pos="0 0 0" rgba=".8 .9 .8 1" size="100 100 .2" type="plane"/>
    <body name="Hips" pos="0.0000 0.0000 1.0000" user="0.0000 0.0003 1.0000">
      <joint armature="0" damping="0" limited="false" name="Hips" pos="0.0000 0.0000 1.0000" stiffness="0" type="free"/>
      <geom pos="0.0000 0.0000 0.9780" size="0.0950" type="sphere"/>
      <body name="RightUpLeg" pos="-0.1272 0.0000 1.0000" user="-0.1272 -0.4343 1.0000">
        <joint axis="0.0000 0.0000 1.0000" name="RightUpLeg_z" pos="-0.1272 0.0000 1.0000" range="-1800.0 1800.0" type="hinge"/>
        <joint axis="1.0000 0.0000 0.0000" name="RightUpLeg_x" pos="-0.1272 0.0000 1.0000" range="-1800.0 1800.0" type="hinge"/>
        <joint axis="0.0000 1.0000 0.0000" name="RightUpLeg_y" pos="-0.1272 0.0000 1.0000" range="-1800.0 1800.0" type="hinge"/>
        <geom contype="1" conaffinity="1" fromto="-0.1272 -0.0200 1.0000 -0.1272 -0.4143 1.0000" size="0.0490" type="capsule"/>
        <body name="RightLeg" pos="-0.1272 -0.4343 1.0000" user="-0.1272 -0.8831 1.0000">
          <joint axis="1.0000 0.0000 0.0000" name="RightLeg_x" pos="-0.1272 -0.4343 1.0000" range="-1800.0 1800.0" type="hinge"/>
          <geom contype="1" conaffinity="1" fromto="-0.1272 -0.4543 1.0000 -0.1272 -0.8631 1.0000" size="0.0400" type="capsule"/>
          <body name="RightFoot" pos="-0.1272 -0.8831 1.0000" user="-0.1272 -0.8831 1.1515">
            <geom contype="1" conaffinity="1" pos="-0.1272 -0.8831 1.0477" size="0.0620 0.0300 0.1000" quat="0.9952 -0.0871 0.0038 -0.0435" type="box"/>
            <joint axis="0.0000 0.0000 1.0000" name="RightFoot_z" pos="-0.1272 -0.8831 1.0000" range="-1800.0 1800.0" type="hinge"/>
            <joint axis="1.0000 0.0000 0.0000" name="RightFoot_x" pos="-0.1272 -0.8831 1.0000" range="-1800.0 1800.0" type="hinge"/>
            <joint axis="0.0000 1.0000 0.0000" name="RightFoot_y" pos="-0.1272 -0.8831 1.0000" range="-1800.0 1800.0" type="hinge"/>
          </body>
        </body>
      </body>
      <body name="LeftUpLeg" pos="0.1272 0.0000 1.0000" user="0.1272 -0.4343 1.0000">
        <joint axis="0.0000 0.0000 1.0000" name="LeftUpLeg_z" pos="0.1272 0.0000 1.0000" range="-1800.0 1800.0" type="hinge"/>
        <joint axis="1.0000 0.0000 0.0000" name="LeftUpLeg_x" pos="0.1272 0.0000 1.0000" range="-1800.0 1800.0" type="hinge"/>
        <joint axis="0.0000 1.0000 0.0000" name="LeftUpLeg_y" pos="0.1272 0.0000 1.0000" range="-1800.0 1800.0" type="hinge"/>
        <geom contype="2" conaffinity="2" fromto="0.1272 -0.0200 1.0000 0.1272 -0.4143 1.0000" size="0.0490" type="capsule"/>
        <body name="LeftLeg" pos="0.1272 -0.4343 1.0000" user="0.1272 -0.8831 1.0000">
          <joint axis="1.0000 0.0000 0.0000" name="LeftLeg_x" pos="0.1272 -0.4343 1.0000" range="-1800.0 1800.0" type="hinge"/>
          <geom contype="2" conaffinity="2" fromto="0.1272 -0.4543 1.0000 0.1272 -0.8631 1.0000" size="0.0400" type="capsule"/>
          <body name="LeftFoot" pos="0.1272 -0.8831 1.0000" user="0.1272 -0.8831 1.1515">
            <geom contype="2" conaffinity="2" pos="0.1272 -0.8831 1.0477" size="0.0620 0.0300 0.1000" quat="0.9952 -0.0871 -0.0038 0.0435" type="box"/>
            <joint axis="0.0000 0.0000 1.0000" name="LeftFoot_z" pos="0.1272 -0.8831 1.0000" range="-1800.0 1800.0" type="hinge"/>
            <joint axis="1.0000 0.0000 0.0000" name="LeftFoot_x" pos="0.1272 -0.8831 1.0000" range="-1800.0 1800.0" type="hinge"/>
            <joint axis="0.0000 1.0000 0.0000" name="LeftFoot_y" pos="0.1272 -0.8831 1.0000" range="-1800.0 1800.0" type="hinge"/>
          </body>
        </body>
      </body>
      <body name="Spine" pos="0.0000 0.0010 1.0000" user="0.0000 0.2469 1.0000">
        <geom fromto="-0.0700 0.1240 1.0000 0.0700 0.1240 1.0000" size="0.0450" type="capsule"/>
        <geom fromto="-0.0700 0.2160 1.0000 0.0700 0.2160 1.0000" size="0.0450" type="capsule"/>
        <joint axis="0.0000 0.0000 1.0000" name="Spine_z" pos="0.0000 0.0010 1.0000" range="-1800.0 1800.0" type="hinge"/>
        <joint axis="1.0000 0.0000 0.0000" name="Spine_x" pos="0.0000 0.0010 1.0000" range="-1800.0 1800.0" type="hinge"/>
        <joint axis="0.0000 1.0000 0.0000" name="Spine_y" pos="0.0000 0.0010 1.0000" range="-1800.0 1800.0" type="hinge"/>
        <body name="Spine1" pos="0.0000 0.2469 1.0000" user="0.0000 0.4954 1.0000">
          <geom fromto="-0.0700 0.3091 1.0000 0.0700 0.3091 1.0000" size="0.0450" type="capsule"/>
          <geom fromto="-0.0700 0.4011 1.0000 0.0700 0.4011 1.0000" size="0.0450" type="capsule"/>
          <joint axis="0.0000 0.0000 1.0000" name="Spine1_z" pos="0.0000 0.2469 1.0000" range="-1800.0 1800.0" type="hinge"/>
          <joint axis="1.0000 0.0000 0.0000" name="Spine1_x" pos="0.0000 0.2469 1.0000" range="-1800.0 1800.0" type="hinge"/>
          <joint axis="0.0000 1.0000 0.0000" name="Spine1_y" pos="0.0000 0.2469 1.0000" range="-1800.0 1800.0" type="hinge"/>
          <body name="Neck" pos="0.0000 0.4954 1.0000" user="0.0000 0.5881 1.0000">
            <joint axis="0.0000 0.0000 1.0000" name="Neck_z" pos="0.0000 0.4954 1.0000" range="-1800.0 1800.0" type="hinge"/>
            <joint axis="1.0000 0.0000 0.0000" name="Neck_x" pos="0.0000 0.4954 1.0000" range="-1800.0 1800.0" type="hinge"/>
            <joint axis="0.0000 1.0000 0.0000" name="Neck_y" pos="0.0000 0.4954 1.0000" range="-1800.0 1800.0" type="hinge"/>
            <geom fromto="0.0000 0.4754 1.0000 0.0000 0.5281 1.0000" size="0.0300" type="capsule"/>
            <body name="Head" pos="0.0000 0.5881 1.0000" user="0.0000 0.7031 1.0000">
              <geom pos="0.0000 0.6401 0.9660" size="0.0750" type="sphere"/>
              <joint axis="0.0000 0.0000 1.0000" name="Head_z" pos="0.0000 0.5881 1.0000" range="-1800.0 1800.0" type="hinge"/>
              <joint axis="1.0000 0.0000 0.0000" name="Head_x" pos="0.0000 0.5881 1.0000" range="-1800.0 1800.0" type="hinge"/>
              <joint axis="0.0000 1.0000 0.0000" name="Head_y" pos="0.0000 0.5881 1.0000" range="-1800.0 1800.0" type="hinge"/>
            </body>
          </body>
          <body name="LeftShoulder" pos="0.0000 0.4954 1.0000" user="0.0000 0.6203 1.0000">
            <joint axis="0.0000 0.0000 1.0000" name="LeftShoulder_z" pos="0.0000 0.4954 1.0000" range="-1800.0 1800.0" type="hinge"/>
            <joint axis="1.0000 0.0000 0.0000" name="LeftShoulder_x" pos="0.0000 0.4954 1.0000" range="-1800.0 1800.0" type="hinge"/>
            <joint axis="0.0000 1.0000 0.0000" name="LeftShoulder_y" pos="0.0000 0.4954 1.0000" range="-1800.0 1800.0" type="hinge"/>
            <geom fromto="0.0000 0.5154 1.0000 0.0000 0.6003 1.0000" size="0.0400" type="capsule"/>
            <body name="LeftArm" pos="0.0000 0.6203 1.0000" user="0.0000 0.8800 1.0000">
              <joint axis="0.0000 0.0000 1.0000" name="LeftArm_z" pos="0.0000 0.6203 1.0000" range="-1800.0 1800.0" type="hinge"/>
              <joint axis="1.0000 0.0000 0.0000" name="LeftArm_x" pos="0.0000 0.6203 1.0000" range="-1800.0 1800.0" type="hinge"/>
              <joint axis="0.0000 1.0000 0.0000" name="LeftArm_y" pos="0.0000 0.6203 1.0000" range="-1800.0 1800.0" type="hinge"/>
              <geom fromto="0.0000 0.6403 1.0000 0.0000 0.8600 1.0000" size="0.0340" type="capsule"/>
              <body name="LeftForeArm" pos="0.0000 0.8800 1.0000" user="0.0000 1.1256 1.0000">
                <joint axis="1.0000 0.0000 0.0000" name="LeftForeArm_x" pos="0.0000 0.8800 1.0000" range="-1800.0 1800.0" type="hinge"/>
                <geom fromto="0.0000 0.9000 1.0000 0.0000 1.1056 1.0000" size="0.0300" type="capsule"/>
                <body name="LeftHand" pos="0.0000 1.1256 1.0000" user="0.0000 1.1256 1.0000">
                  <geom pos="0.0000 1.1256 1.0000" size="0.0400" type="sphere"/>
                  <joint axis="0.0000 0.0000 1.0000" name="LeftHand_z" pos="0.0000 1.1256 1.0000" range="-1800.0 1800.0" type="hinge"/>
                  <joint axis="1.0000 0.0000 0.0000" name="LeftHand_x" pos="0.0000 1.1256 1.0000" range="-1800.0 1800.0" type="hinge"/>
                  <joint axis="0.0000 1.0000 0.0000" name="LeftHand_y" pos="0.0000 1.1256 1.0000" range="-1800.0 1800.0" type="hinge"/>
                </body>
              </body>
            </body>
          </body>
          <body name="RightShoulder" pos="-0.0000 0.4954 1.0000" user="0.0000 0.6203 1.0000">
            <joint axis="0.0000 0.0000 1.0000" name="RightShoulder_z" pos="0.0000 0.4954 1.0000" range="-1800.0 1800.0" type="hinge"/>
            <joint axis="1.0000 0.0000 0.0000" name="RightShoulder_x" pos="0.0000 0.4954 1.0000" range="-1800.0 1800.0" type="hinge"/>
            <joint axis="0.0000 1.0000 0.0000" name="RightShoulder_y" pos="0.0000 0.4954 1.0000" range="-1800.0 1800.0" type="hinge"/>
            <geom fromto="-0.0000 0.5154 1.0000 -0.0000 0.6003 1.0000" size="0.0400" type="capsule"/>
            <body name="RightArm" pos="-0.0000 0.6203 1.0000" user="0.0000 0.8800 1.0000">
              <joint axis="0.0000 0.0000 1.0000" name="RightArm_z" pos="0.0000 0.6203 1.0000" range="-1800.0 1800.0" type="hinge"/>
              <joint axis="1.0000 0.0000 0.0000" name="RightArm_x" pos="0.0000 0.6203 1.0000" range="-1800.0 1800.0" type="hinge"/>
              <joint axis="0.0000 1.0000 0.0000" name="RightArm_y" pos="0.0000 0.6203 1.0000" range="-1800.0 1800.0" type="hinge"/>
              <geom fromto="-0.0000 0.6403 1.0000 -0.0000 0.8600 1.0000" size="0.0340" type="capsule"/>
              <body name="RightForeArm" pos="-0.0000 0.8800 1.0000" user="0.0000 1.1256 1.0000">
                <joint axis="1.0000 0.0000 0.0000" name="RightForeArm_x" pos="0.0000 0.8800 1.0000" range="-1800.0 1800.0" type="hinge"/>
                <geom fromto="-0.0000 0.9000 1.0000 -0.0000 1.1056 1.0000" size="0.0300" type="capsule"/>
                <body name="RightHand" pos="-0.0000 1.1256 1.0000" user="0.0000 1.1256 1.0000">
                  <geom pos="-0.0000 1.1256 1.0000" size="0.0400" type="sphere"/>
                  <joint axis="0.0000 0.0000 1.0000" name="RightHand_z" pos="0.0000 1.1256 1.0000" range="-1800.0 1800.0" type="hinge"/>
                  <joint axis="1.0000 0.0000 0.0000" name="RightHand_x" pos="0.0000 1.1256 1.0000" range="-1800.0 1800.0" type="hinge"/>
                  <joint axis="0.0000 1.0000 0.0000" name="RightHand_y" pos="0.0000 1.1256 1.0000" range="-1800.0 1800.0" type="hinge"/>
                </body>
              </body>
            </body>
          </body>
        </body>
      </body>
    </body>
    <body name="1_Hips" pos="0.0000 0.0000 1.0000" user="0.0000 0.0003 1.0000">
      <joint armature="0" damping="0" limited="false" name="1_Hips" pos="0.0000 0.0000 1.0000" stiffness="0" type="free"/>
      <geom pos="0.0000 0.0000 0.9780" size="0.0950" type="sphere"/>
      <body name="1_RightUpLeg" pos="-0.1272 0.0000 1.0000" user="-0.1272 -0.4343 1.0000">
        <joint axis="0.0000 0.0000 1.0000" name="1_RightUpLeg_z" pos="-0.1272 0.0000 1.0000" range="-1800.0 1800.0" type="hinge"/>
        <joint axis="1.0000 0.0000 0.0000" name="1_RightUpLeg_x" pos="-0.1272 0.0000 1.0000" range="-1800.0 1800.0" type="hinge"/>
        <joint axis="0.0000 1.0000 0.0000" name="1_RightUpLeg_y" pos="-0.1272 0.0000 1.0000" range="-1800.0 1800.0" type="hinge"/>
        <geom contype="1" conaffinity="1" fromto="-0.1272 -0.0200 1.0000 -0.1272 -0.4143 1.0000" size="0.0490" type="capsule"/>
        <body name="1_RightLeg" pos="-0.1272 -0.4343 1.0000" user="-0.1272 -0.8831 1.0000">
          <joint axis="1.0000 0.0000 0.0000" name="1_RightLeg_x" pos="-0.1272 -0.4343 1.0000" range="-1800.0 1800.0" type="hinge"/>
          <geom contype="1" conaffinity="1" fromto="-0.1272 -0.4543 1.0000 -0.1272 -0.8631 1.0000" size="0.0400" type="capsule"/>
          <body name="1_RightFoot" pos="-0.1272 -0.8831 1.0000" user="-0.1272 -0.8831 1.1515">
            <geom contype="1" conaffinity="1" pos="-0.1272 -0.8831 1.0477" size="0.0620 0.0300 0.1000" quat="0.9952 -0.0871 0.0038 -0.0435" type="box"/>
            <joint axis="0.0000 0.0000 1.0000" name="1_RightFoot_z" pos="-0.1272 -0.8831 1.0000" range="-1800.0 1800.0" type="hinge"/>
            <joint axis="1.0000 0.0000 0.0000" name="1_RightFoot_x" pos="-0.1272 -0.8831 1.0000" range="-1800.0 1800.0" type="hinge"/>
            <joint axis="0.0000 1.0000 0.0000" name="1_RightFoot_y" pos="-0.1272 -0.8831 1.0000" range="-1800.0 1800.0" type="hinge"/>
          </body>
        </body>
      </body>
      <body name="1_LeftUpLeg" pos="0.1272 0.0000 1.0000" user="0.1272 -0.4343 1.0000">
        <joint axis="0.0000 0.0000 1.0000" name="1_LeftUpLeg_z" pos="0.1272 0.0000 1.0000" range="-1800.0 1800.0" type="hinge"/>
        <joint axis="1.0000 0.0000 0.0000" name="1_LeftUpLeg_x" pos="0.1272 0.0000 1.0000" range="-1800.0 1800.0" type="hinge"/>
        <joint axis="0.0000 1.0000 0.0000" name="1_LeftUpLeg_y" pos="0.1272 0.0000 1.0000" range="-1800.0 1800.0" type="hinge"/>
        <geom contype="2" conaffinity="2" fromto="0.1272 -0.0200 1.0000 0.1272 -0.4143 1.0000" size="0.0490" type="capsule"/>
        <body name="1_LeftLeg" pos="0.1272 -0.4343 1.0000" user="0.1272 -0.8831 1.0000">
          <joint axis="1.0000 0.0000 0.0000" name="1_LeftLeg_x" pos="0.1272 -0.4343 1.0000" range="-1800.0 1800.0" type="hinge"/>
          <geom contype="2" conaffinity="2" fromto="0.1272 -0.4543 1.0000 0.1272 -0.8631 1.0000" size="0.0400" type="capsule"/>
          <body name="1_LeftFoot" pos="0.1272 -0.8831 1.0000" user="0.1272 -0.8831 1.1515">
            <geom contype="2" conaffinity="2" pos="0.1272 -0.8831 1.0477" size="0.0620 0.0300 0.1000" quat="0.9952 -0.0871 -0.0038 0.0435" type="box"/>
            <joint axis="0.0000 0.0000 1.0000" name="1_LeftFoot_z" pos="0.1272 -0.8831 1.0000" range="-1800.0 1800.0" type="hinge"/>
            <joint axis="1.0000 0.0000 0.0000" name="1_LeftFoot_x" pos="0.1272 -0.8831 1.0000" range="-1800.0 1800.0" type="hinge"/>
            <joint axis="0.0000 1.0000 0.0000" name="1_LeftFoot_y" pos="0.1272 -0.8831 1.0000" range="-1800.0 1800.0" type="hinge"/>
          </body>
        </body>
      </body>
      <body name="1_Spine" pos="0.0000 0.0010 1.0000" user="0.0000 0.2469 1.0000">
        <geom fromto="-0.0700 0.1240 1.0000 0.0700 0.1240 1.0000" size="0.0450" type="capsule"/>
        <geom fromto="-0.0700 0.2160 1.0000 0.0700 0.2160 1.0000" size="0.0450" type="capsule"/>
        <joint axis="0.0000 0.0000 1.0000" name="1_Spine_z" pos="0.0000 0.0010 1.0000" range="-1800.0 1800.0" type="hinge"/>
        <joint axis="1.0000 0.0000 0.0000" name="1_Spine_x" pos="0.0000 0.0010 1.0000" range="-1800.0 1800.0" type="hinge"/>
        <joint axis="0.0000 1.0000 0.0000" name="1_Spine_y" pos="0.0000 0.0010 1.0000" range="-1800.0 1800.0" type="hinge"/>
        <body name="1_Spine1" pos="0.0000 0.2469 1.0000" user="0.0000 0.4954 1.0000">
          <geom fromto="-0.0700 0.3091 1.0000 0.0700 0.3091 1.0000" size="0.0450" type="capsule"/>
          <geom fromto="-0.0700 0.4011 1.0000 0.0700 0.4011 1.0000" size="0.0450" type="capsule"/>
          <joint axis="0.0000 0.0000 1.0000" name="1_Spine1_z" pos="0.0000 0.2469 1.0000" range="-1800.0 1800.0" type="hinge"/>
          <joint axis="1.0000 0.0000 0.0000" name="1_Spine1_x" pos="0.0000 0.2469 1.0000" range="-1800.0 1800.0" type="hinge"/>
          <joint axis="0.0000 1.0000 0.0000" name="1_Spine1_y" pos="0.0000 0.2469 1.0000" range="-1800.0 1800.0" type="hinge"/>
          <body name="1_Neck" pos="0.0000 0.4954 1.0000" user="0.0000 0.5881 1.0000">
            <joint axis="0.0000 0.0000 1.0000" name="1_Neck_z" pos="0.0000 0.4954 1.0000" range="-1800.0 1800.0" type="hinge"/>
            <joint axis="1.0000 0.0000 0.0000" name="1_Neck_x" pos="0.0000 0.4954 1.0000" range="-1800.0 1800.0" type="hinge"/>
            <joint axis="0.0000 1.0000 0.0000" name="1_Neck_y" pos="0.0000 0.4954 1.0000" range="-1800.0 1800.0" type="hinge"/>
            <geom fromto="0.0000 0.4754 1.0000 0.0000 0.5281 1.0000" size="0.0300" type="capsule"/>
            <body name="1_Head" pos="0.0000 0.5881 1.0000" user="0.0000 0.7031 1.0000">
              <geom pos="0.0000 0.6401 0.9660" size="0.0750" type="sphere"/>
              <joint axis="0.0000 0.0000 1.0000" name="1_Head_z" pos="0.0000 0.5881 1.0000" range="-1800.0 1800.0" type="hinge"/>
              <joint axis="1.0000 0.0000 0.0000" name="1_Head_x" pos="0.0000 0.5881 1.0000" range="-1800.0 1800.0" type="hinge"/>
              <joint axis="0.0000 1.0000 0.0000" name="1_Head_y" pos="0.0000 0.5881 1.0000" range="-1800.0 1800.0" type="hinge"/>
            </body>
          </body>
          <body name="1_LeftShoulder" pos="0.0000 0.4954 1.0000" user="0.0000 0.6203 1.0000">
            <joint axis="0.0000 0.0000 1.0000" name="1_LeftShoulder_z" pos="0.0000 0.4954 1.0000" range="-1800.0 1800.0" type="hinge"/>
            <joint axis="1.0000 0.0000 0.0000" name="1_LeftShoulder_x" pos="0.0000 0.4954 1.0000" range="-1800.0 1800.0" type="hinge"/>
            <joint axis="0.0000 1.0000 0.0000" name="1_LeftShoulder_y" pos="0.0000 0.4954 1.0000" range="-1800.0 1800.0" type="hinge"/>
            <geom fromto="0.0000 0.5154 1.0000 0.0000 0.6003 1.0000" size="0.0400" type="capsule"/>
            <body name="1_LeftArm" pos="0.0000 0.6203 1.0000" user="0.0000 0.8800 1.0000">
              <joint axis="0.0000 0.0000 1.0000" name="1_LeftArm_z" pos="0.0000 0.6203 1.0000" range="-1800.0 1800.0" type="hinge"/>
              <joint axis="1.0000 0.0000 0.0000" name="1_LeftArm_x" pos="0.0000 0.6203 1.0000" range="-1800.0 1800.0" type="hinge"/>
              <joint axis="0.0000 1.0000 0.0000" name="1_LeftArm_y" pos="0.0000 0.6203 1.0000" range="-1800.0 1800.0" type="hinge"/>
              <geom fromto="0.0000 0.6403 1.0000 0.0000 0.8600 1.0000" size="0.0340" type="capsule"/>
              <body name="1_LeftForeArm" pos="0.0000 0.8800 1.0000" user="0.0000 1.1256 1.0000">
                <joint axis="1.0000 0.0000 0.0000" name="1_LeftForeArm_x" pos="0.0000 0.8800 1.0000" range="-1800.0 1800.0" type="hinge"/>
                <geom fromto="0.0000 0.9000 1.0000 0.0000 1.1056 1.0000" size="0.0300" type="capsule"/>
                <body name="1_LeftHand" pos="0.0000 1.1256 1.0000" user="0.0000 1.1256 1.0000">
                  <geom pos="0.0000 1.1256 1.0000" size="0.0400" type="sphere"/>
                  <joint axis="0.0000 0.0000 1.0000" name="1_LeftHand_z" pos="0.0000 1.1256 1.0000" range="-1800.0 1800.0" type="hinge"/>
                  <joint axis="1.0000 0.0000 0.0000" name="1_LeftHand_x" pos="0.0000 1.1256 1.0000" range="-1800.0 1800.0" type="hinge"/>
                  <joint axis="0.0000 1.0000 0.0000" name="1_LeftHand_y" pos="0.0000 1.1256 1.0000" range="-1800.0 1800.0" type="hinge"/>
                </body>
              </body>
            </body>
          </body>
          <body name="1_RightShoulder" pos="-0.0000 0.4954 1.0000" user="0.0000 0.6203 1.0000">
            <joint axis="0.0000 0.0000 1.0000" name="1_RightShoulder_z" pos="0.0000 0.4954 1.0000" range="-1800.0 1800.0" type="hinge"/>
            <joint axis="1.0000 0.0000 0.0000" name="1_RightShoulder_x" pos="0.0000 0.4954 1.0000" range="-1800.0 1800.0" type="hinge"/>
            <joint axis="0.0000 1.0000 0.0000" name="1_RightShoulder_y" pos="0.0000 0.4954 1.0000" range="-1800.0 1800.0" type="hinge"/>
            <geom fromto="-0.0000 0.5154 1.0000 -0.0000 0.6003 1.0000" size="0.0400" type="capsule"/>
            <body name="1_RightArm" pos="-0.0000 0.6203 1.0000" user="0.0000 0.8800 1.0000">
              <joint axis="0.0000 0.0000 1.0000" name="1_RightArm_z" pos="0.0000 0.6203 1.0000" range="-1800.0 1800.0" type="hinge"/>
              <joint axis="1.0000 0.0000 0.0000" name="1_RightArm_x" pos="0.0000 0.6203 1.0000" range="-1800.0 1800.0" type="hinge"/>
              <joint axis="0.0000 1.0000 0.0000" name="1_RightArm_y" pos="0.0000 0.6203 1.0000" range="-1800.0 1800.0" type="hinge"/>
              <geom fromto="-0.0000 0.6403 1.0000 -0.0000 0.8600 1.0000" size="0.0340" type="capsule"/>
              <body name="1_RightForeArm" pos="-0.0000 0.8800 1.0000" user="0.0000 1.1256 1.0000">
                <joint axis="1.0000 0.0000 0.0000" name="1_RightForeArm_x" pos="0.0000 0.8800 1.0000" range="-1800.0 1800.0" type="hinge"/>
                <geom fromto="-0.0000 0.9000 1.0000 -0.0000 1.1056 1.0000" size="0.0300" type="capsule"/>
                <body name="1_RightHand" pos="-0.0000 1.1256 1.0000" user="0.0000 1.1256 1.0000">
                  <geom pos="-0.0000 1.1256 1.0000" size="0.0400" type="sphere"/>
                  <joint axis="0.0000 0.0000 1.0000" name="1_RightHand_z" pos="0.0000 1.1256 1.0000" range="-1800.0 1800.0" type="hinge"/>
                  <joint axis="1.0000 0.0000 0.0000" name="1_RightHand_x" pos="0.0000 1.1256 1.0000" range="-1800.0 1800.0" type="hinge"/>
                  <joint axis="0.0000 1.0000 0.0000" name="1_RightHand_y" pos="0.0000 1.1256 1.0000" range="-1800.0 1800.0" type="hinge"/>
                </body>
              </body>
            </body>
          </body>
        </body>
      </body>
    </body>
    <body name="2_Hips" pos="0.0000 0.0000 1.0000" user="0.0000 0.0003 1.0000">
      <joint armature="0" damping="0" limited="false" name="2_Hips" pos="0.0000 0.0000 1.0000" stiffness="0" type="free"/>
      <geom pos="0.0000 0.0000 0.9780" size="0.0950" type="sphere"/>
      <body name="2_RightUpLeg" pos="-0.1272 0.0000 1.0000" user="-0.1272 -0.4343 1.0000">
        <joint axis="0.0000 0.0000 1.0000" name="2_RightUpLeg_z" pos="-0.1272 0.0000 1.0000" range="-1800.0 1800.0" type="hinge"/>
        <joint axis="1.0000 0.0000 0.0000" name="2_RightUpLeg_x" pos="-0.1272 0.0000 1.0000" range="-1800.0 1800.0" type="hinge"/>
        <joint axis="0.0000 1.0000 0.0000" name="2_RightUpLeg_y" pos="-0.1272 0.0000 1.0000" range="-1800.0 1800.0" type="hinge"/>
        <geom contype="1" conaffinity="1" fromto="-0.1272 -0.0200 1.0000 -0.1272 -0.4143 1.0000" size="0.0490" type="capsule"/>
        <body name="2_RightLeg" pos="-0.1272 -0.4343 1.0000" user="-0.1272 -0.8831 1.0000">
          <joint axis="1.0000 0.0000 0.0000" name="2_RightLeg_x" pos="-0.1272 -0.4343 1.0000" range="-1800.0 1800.0" type="hinge"/>
          <geom contype="1" conaffinity="1" fromto="-0.1272 -0.4543 1.0000 -0.1272 -0.8631 1.0000" size="0.0400" type="capsule"/>
          <body name="2_RightFoot" pos="-0.1272 -0.8831 1.0000" user="-0.1272 -0.8831 1.1515">
            <geom contype="1" conaffinity="1" pos="-0.1272 -0.8831 1.0477" size="0.0620 0.0300 0.1000" quat="0.9952 -0.0871 0.0038 -0.0435" type="box"/>
            <joint axis="0.0000 0.0000 1.0000" name="2_RightFoot_z" pos="-0.1272 -0.8831 1.0000" range="-1800.0 1800.0" type="hinge"/>
            <joint axis="1.0000 0.0000 0.0000" name="2_RightFoot_x" pos="-0.1272 -0.8831 1.0000" range="-1800.0 1800.0" type="hinge"/>
            <joint axis="0.0000 1.0000 0.0000" name="2_RightFoot_y" pos="-0.1272 -0.8831 1.0000" range="-1800.0 1800.0" type="hinge"/>
          </body>
        </body>
      </body>
      <body name="2_LeftUpLeg" pos="0.1272 0.0000 1.0000" user="0.1272 -0.4343 1.0000">
        <joint axis="0.0000 0.0000 1.0000" name="2_LeftUpLeg_z" pos="0.1272 0.0000 1.0000" range="-1800.0 1800.0" type="hinge"/>
        <joint axis="1.0000 0.0000 0.0000" name="2_LeftUpLeg_x" pos="0.1272 0.0000 1.0000" range="-1800.0 1800.0" type="hinge"/>
        <joint axis="0.0000 1.0000 0.0000" name="2_LeftUpLeg_y" pos="0.1272 0.0000 1.0000" range="-1800.0 1800.0" type="hinge"/>
        <geom contype="2" conaffinity="2" fromto="0.1272 -0.0200 1.0000 0.1272 -0.4143 1.0000" size="0.0490" type="capsule"/>
        <body name="2_LeftLeg" pos="0.1272 -0.4343 1.0000" user="0.1272 -0.8831 1.0000">
          <joint axis="1.0000 0.0000 0.0000" name="2_LeftLeg_x" pos="0.1272 -0.4343 1.0000" range="-1800.0 1800.0" type="hinge"/>
          <geom contype="2" conaffinity="2" fromto="0.1272 -0.4543 1.0000 0.1272 -0.8631 1.0000" size="0.0400" type="capsule"/>
          <body name="2_LeftFoot" pos="0.1272 -0.8831 1.0000" user="0.1272 -0.8831 1.1515">
            <geom contype="2" conaffinity="2" pos="0.1272 -0.8831 1.0477" size="0.0620 0.0300 0.1000" quat="0.9952 -0.0871 -0.0038 0.0435" type="box"/>
            <joint axis="0.0000 0.0000 1.0000" name="2_LeftFoot_z" pos="0.1272 -0.8831 1.0000" range="-1800.0 1800.0" type="hinge"/>
            <joint axis="1.0000 0.0000 0.0000" name="2_LeftFoot_x" pos="0.1272 -0.8831 1.0000" range="-1800.0 1800.0" type="hinge"/>
            <joint axis="0.0000 1.0000 0.0000" name="2_LeftFoot_y" pos="0.1272 -0.8831 1.0000" range="-1800.0 1800.0" type="hinge"/>
          </body>
        </body>
      </body>
      <body name="2_Spine" pos="0.0000 0.0010 1.0000" user="0.0000 0.2469 1.0000">
        <geom fromto="-0.0700 0.1240 1.0000 0.0700 0.1240 1.0000" size="0.0450" type="capsule"/>
        <geom fromto="-0.0700 0.2160 1.0000 0.0700 0.2160 1.0000" size="0.0450" type="capsule"/>
        <joint axis="0.0000 0.0000 1.0000" name="2_Spine_z" pos="0.0000 0.0010 1.0000" range="-1800.0 1800.0" type="hinge"/>
        <joint axis="1.0000 0.0000 0.0000" name="2_Spine_x" pos="0.0000 0.0010 1.0000" range="-1800.0 1800.0" type="hinge"/>
        <joint axis="0.0000 1.0000 0.0000" name="2_Spine_y" pos="0.0000 0.0010 1.0000" range="-1800.0 1800.0" type="hinge"/>
        <body name="2_Spine1" pos="0.0000 0.2469 1.0000" user="0.0000 0.4954 1.0000">
          <geom fromto="-0.0700 0.3091 1.0000 0.0700 0.3091 1.0000" size="0.0450" type="capsule"/>
          <geom fromto="-0.0700 0.4011 1.0000 0.0700 0.4011 1.0000" size="0.0450" type="capsule"/>
          <joint axis="0.0000 0.0000 1.0000" name="2_Spine1_z" pos="0.0000 0.2469 1.0000" range="-1800.0 1800.0" type="hinge"/>
          <joint axis="1.0000 0.0000 0.0000" name="2_Spine1_x" pos="0.0000 0.2469 1.0000" range="-1800.0 1800.0" type="hinge"/>
          <joint axis="0.0000 1.0000 0.0000" name="2_Spine1_y" pos="0.0000 0.2469 1.0000" range="-1800.0 1800.0" type="hinge"/>
          <body name="2_Neck" pos="0.0000 0.4954 1.0000" user="0.0000 0.5881 1.0000">
            <joint axis="0.0000 0.0000 1.0000" name="2_Neck_z" pos="0.0000 0.4954 1.0000" range="-1800.0 1800.0" type="hinge"/>
            <joint axis="1.0000 0.0000 0.0000" name="2_Neck_x" pos="0.0000 0.4954 1.0000" range="-1800.0 1800.0" type="hinge"/>
            <joint axis="0.0000 1.0000 0.0000" name="2_Neck_y" pos="0.0000 0.4954 1.0000" range="-1800.0 1800.0" type="hinge"/>
            <geom fromto="0.0000 0.4754 1.0000 0.0000 0.5281 1.0000" size="0.0300" type="capsule"/>
            <body name="2_Head" pos="0.0000 0.5881 1.0000" user="0.0000 0.7031 1.0000">
              <geom pos="0.0000 0.6401 0.9660" size="0.0750" type="sphere"/>
              <joint axis="0.0000 0.0000 1.0000" name="2_Head_z" pos="0.0000 0.5881 1.0000" range="-1800.0 1800.0" type="hinge"/>
              <joint axis="1.0000 0.0000 0.0000" name="2_Head_x" pos="0.0000 0.5881 1.0000" range="-1800.0 1800.0" type="hinge"/>
              <joint axis="0.0000 1.0000 0.0000" name="2_Head_y" pos="0.0000 0.5881 1.0000" range="-1800.0 1800.0" type="hinge"/>
            </body>
          </body>
          <body name="2_LeftShoulder" pos="0.0000 0.4954 1.0000" user="0.0000 0.6203 1.0000">
            <joint axis="0.0000 0.0000 1.0000" name="2_LeftShoulder_z" pos="0.0000 0.4954 1.0000" range="-1800.0 1800.0" type="hinge"/>
            <joint axis="1.0000 0.0000 0.0000" name="2_LeftShoulder_x" pos="0.0000 0.4954 1.0000" range="-1800.0 1800.0" type="hinge"/>
            <joint axis="0.0000 1.0000 0.0000" name="2_LeftShoulder_y" pos="0.0000 0.4954 1.0000" range="-1800.0 1800.0" type="hinge"/>
            <geom fromto="0.0000 0.5154 1.0000 0.0000 0.6003 1.0000" size="0.0400" type="capsule"/>
            <body name="2_LeftArm" pos="0.0000 0.6203 1.0000" user="0.0000 0.8800 1.0000">
              <joint axis="0.0000 0.0000 1.0000" name="2_LeftArm_z" pos="0.0000 0.6203 1.0000" range="-1800.0 1800.0" type="hinge"/>
              <joint axis="1.0000 0.0000 0.0000" name="2_LeftArm_x" pos="0.0000 0.6203 1.0000" range="-1800.0 1800.0" type="hinge"/>
              <joint axis="0.0000 1.0000 0.0000" name="2_LeftArm_y" pos="0.0000 0.6203 1.0000" range="-1800.0 1800.0" type="hinge"/>
              <geom fromto="0.0000 0.6403 1.0000 0.0000 0.8600 1.0000" size="0.0340" type="capsule"/>
              <body name="2_LeftForeArm" pos="0.0000 0.8800 1.0000" user="0.0000 1.1256 1.0000">
                <joint axis="1.0000 0.0000 0.0000" name="2_LeftForeArm_x" pos="0.0000 0.8800 1.0000" range="-1800.0 1800.0" type="hinge"/>
                <geom fromto="0.0000 0.9000 1.0000 0.0000 1.1056 1.0000" size="0.0300" type="capsule"/>
                <body name="2_LeftHand" pos="0.0000 1.1256 1.0000" user="0.0000 1.1256 1.0000">
                  <geom pos="0.0000 1.1256 1.0000" size="0.0400" type="sphere"/>
                  <joint axis="0.0000 0.0000 1.0000" name="2_LeftHand_z" pos="0.0000 1.1256 1.0000" range="-1800.0 1800.0" type="hinge"/>
                  <joint axis="1.0000 0.0000 0.0000" name="2_LeftHand_x" pos="0.0000 1.1256 1.0000" range="-1800.0 1800.0" type="hinge"/>
                  <joint axis="0.0000 1.0000 0.0000" name="2_LeftHand_y" pos="0.0000 1.1256 1.0000" range="-1800.0 1800.0" type="hinge"/>
                </body>
              </body>
            </body>
          </body>
          <body name="2_RightShoulder" pos="-0.0000 0.4954 1.0000" user="0.0000 0.6203 1.0000">
            <joint axis="0.0000 0.0000 1.0000" name="2_RightShoulder_z" pos="0.0000 0.4954 1.0000" range="-1800.0 1800.0" type="hinge"/>
            <joint axis="1.0000 0.0000 0.0000" name="2_RightShoulder_x" pos="0.0000 0.4954 1.0000" range="-1800.0 1800.0" type="hinge"/>
            <joint axis="0.0000 1.0000 0.0000" name="2_RightShoulder_y" pos="0.0000 0.4954 1.0000" range="-1800.0 1800.0" type="hinge"/>
            <geom fromto="-0.0000 0.5154 1.0000 -0.0000 0.6003 1.0000" size="0.0400" type="capsule"/>
            <body name="2_RightArm" pos="-0.0000 0.6203 1.0000" user="0.0000 0.8800 1.0000">
              <joint axis="0.0000 0.0000 1.0000" name="2_RightArm_z" pos="0.0000 0.6203 1.0000" range="-1800.0 1800.0" type="hinge"/>
              <joint axis="1.0000 0.0000 0.0000" name="2_RightArm_x" pos="0.0000 0.6203 1.0000" range="-1800.0 1800.0" type="hinge"/>
              <joint axis="0.0000 1.0000 0.0000" name="2_RightArm_y" pos="0.0000 0.6203 1.0000" range="-1800.0 1800.0" type="hinge"/>
              <geom fromto="-0.0000 0.6403 1.0000 -0.0000 0.8600 1.0000" size="0.0340" type="capsule"/>
              <body name="2_RightForeArm" pos="-0.0000 0.8800 1.0000" user="0.0000 1.1256 1.0000">
                <joint axis="1.0000 0.0000 0.0000" name="2_RightForeArm_x" pos="0.0000 0.8800 1.0000" range="-1800.0 1800.0" type="hinge"/>
                <geom fromto="-0.0000 0.9000 1.0000 -0.0000 1.1056 1.0000" size="0.0300" type="capsule"/>
                <body name="2_RightHand" pos="-0.0000 1.1256 1.0000" user="0.0000 1.1256 1.0000">
                  <geom pos="-0.0000 1.1256 1.0000" size="0.0400" type="sphere"/>
                  <joint axis="0.0000 0.0000 1.0000" name="2_RightHand_z" pos="0.0000 1.1256 1.0000" range="-1800.0 1800.0" type="hinge"/>
                  <joint axis="1.0000 0.0000 0.0000" name="2_RightHand_x" pos="0.0000 1.1256 1.0000" range="-1800.0 1800.0" type="hinge"/>
                  <joint axis="0.0000 1.0000 0.0000" name="2_RightHand_y" pos="0.0000 1.1256 1.0000" range="-1800.0 1800.0" type="hinge"/>
                </body>
              </body>
            </body>
          </body>
        </body>
      </body>
    </body>
    <body name="3_Hips" pos="0.0000 0.0000 1.0000" user="0.0000 0.0003 1.0000">
      <joint armature="0" damping="0" limited="false" name="3_Hips" pos="0.0000 0.0000 1.0000" stiffness="0" type="free"/>
      <geom pos="0.0000 0.0000 0.9780" size="0.0950" type="sphere"/>
      <body name="3_RightUpLeg" pos="-0.1272 0.0000 1.0000" user="-0.1272 -0.4343 1.0000">
        <joint axis="0.0000 0.0000 1.0000" name="3_RightUpLeg_z" pos="-0.1272 0.0000 1.0000" range="-1800.0 1800.0" type="hinge"/>
        <joint axis="1.0000 0.0000 0.0000" name="3_RightUpLeg_x" pos="-0.1272 0.0000 1.0000" range="-1800.0 1800.0" type="hinge"/>
        <joint axis="0.0000 1.0000 0.0000" name="3_RightUpLeg_y" pos="-0.1272 0.0000 1.0000" range="-1800.0 1800.0" type="hinge"/>
        <geom contype="1" conaffinity="1" fromto="-0.1272 -0.0200 1.0000 -0.1272 -0.4143 1.0000" size="0.0490" type="capsule"/>
        <body name="3_RightLeg" pos="-0.1272 -0.4343 1.0000" user="-0.1272 -0.8831 1.0000">
          <joint axis="1.0000 0.0000 0.0000" name="3_RightLeg_x" pos="-0.1272 -0.4343 1.0000" range="-1800.0 1800.0" type="hinge"/>
          <geom contype="1" conaffinity="1" fromto="-0.1272 -0.4543 1.0000 -0.1272 -0.8631 1.0000" size="0.0400" type="capsule"/>
          <body name="3_RightFoot" pos="-0.1272 -0.8831 1.0000" user="-0.1272 -0.8831 1.1515">
            <geom contype="1" conaffinity="1" pos="-0.1272 -0.8831 1.0477" size="0.0620 0.0300 0.1000" quat="0.9952 -0.0871 0.0038 -0.0435" type="box"/>
            <joint axis="0.0000 0.0000 1.0000" name="3_RightFoot_z" pos="-0.1272 -0.8831 1.0000" range="-1800.0 1800.0" type="hinge"/>
            <joint axis="1.0000 0.0000 0.0000" name="3_RightFoot_x" pos="-0.1272 -0.8831 1.0000" range="-1800.0 1800.0" type="hinge"/>
            <joint axis="0.0000 1.0000 0.0000" name="3_RightFoot_y" pos="-0.1272 -0.8831 1.0000" range="-1800.0 1800.0" type="hinge"/>
          </body>
        </body>
      </body>
      <body name="3_LeftUpLeg" pos="0.1272 0.0000 1.0000" user="0.1272 -0.4343 1.0000">
        <joint axis="0.0000 0.0000 1.0000" name="3_LeftUpLeg_z" pos="0.1272 0.0000 1.0000" range="-1800.0 1800.0" type="hinge"/>
        <joint axis="1.0000 0.0000 0.0000" name="3_LeftUpLeg_x" pos="0.1272 0.0000 1.0000" range="-1800.0 1800.0" type="hinge"/>
        <joint axis="0.0000 1.0000 0.0000" name="3_LeftUpLeg_y" pos="0.1272 0.0000 1.0000" range="-1800.0 1800.0" type="hinge"/>
        <geom contype="2" conaffinity="2" fromto="0.1272 -0.0200 1.0000 0.1272 -0.4143 1.0000" size="0.0490" type="capsule"/>
        <body name="3_LeftLeg" pos="0.1272 -0.4343 1.0000" user="0.1272 -0.8831 1.0000">
          <joint axis="1.0000 0.0000 0.0000" name="3_LeftLeg_x" pos="0.1272 -0.4343 1.0000" range="-1800.0 1800.0" type="hinge"/>
          <geom contype="2" conaffinity="2" fromto="0.1272 -0.4543 1.0000 0.1272 -0.8631 1.0000" size="0.0400" type="capsule"/>
          <body name="3_LeftFoot" pos="0.1272 -0.8831 1.0000" user="0.1272 -0.8831 1.1515">
            <geom contype="2" conaffinity="2" pos="0.1272 -0.8831 1.0477" size="0.0620 0.0300 0.1000" quat="0.9952 -0.0871 -0.0038 0.0435" type="box"/>
            <joint axis="0.0000 0.0000 1.0000" name="3_LeftFoot_z" pos="0.1272 -0.8831 1.0000" range="-1800.0 1800.0" type="hinge"/>
            <joint axis="1.0000 0.0000 0.0000" name="3_LeftFoot_x" pos="0.1272 -0.8831 1.0000" range="-1800.0 1800.0" type="hinge"/>
            <joint axis="0.0000 1.0000 0.0000" name="3_LeftFoot_y" pos="0.1272 -0.8831 1.0000" range="-1800.0 1800.0" type="hinge"/>
          </body>
        </body>
      </body>
      <body name="3_Spine" pos="0.0000 0.0010 1.0000" user="0.0000 0.2469 1.0000">
        <geom fromto="-0.0700 0.1240 1.0000 0.0700 0.1240 1.0000" size="0.0450" type="capsule"/>
        <geom fromto="-0.0700 0.2160 1.0000 0.0700 0.2160 1.0000" size="0.0450" type="capsule"/>
        <joint axis="0.0000 0.0000 1.0000" name="3_Spine_z" pos="0.0000 0.0010 1.0000" range="-1800.0 1800.0" type="hinge"/>
        <joint axis="1.0000 0.0000 0.0000" name="3_Spine_x" pos="0.0000 0.0010 1.0000" range="-1800.0 1800.0" type="hinge"/>
        <joint axis="0.0000 1.0000 0.0000" name="3_Spine_y" pos="0.0000 0.0010 1.0000" range="-1800.0 1800.0" type="hinge"/>
        <body name="3_Spine1" pos="0.0000 0.2469 1.0000" user="0.0000 0.4954 1.0000">
          <geom fromto="-0.0700 0.3091 1.0000 0.0700 0.3091 1.0000" size="0.0450" type="capsule"/>
          <geom fromto="-0.0700 0.4011 1.0000 0.0700 0.4011 1.0000" size="0.0450" type="capsule"/>
          <joint axis="0.0000 0.0000 1.0000" name="3_Spine1_z" pos="0.0000 0.2469 1.0000" range="-1800.0 1800.0" type="hinge"/>
          <joint axis="1.0000 0.0000 0.0000" name="3_Spine1_x" pos="0.0000 0.2469 1.0000" range="-1800.0 1800.0" type="hinge"/>
          <joint axis="0.0000 1.0000 0.0000" name="3_Spine1_y" pos="0.0000 0.2469 1.0000" range="-1800.0 1800.0" type="hinge"/>
          <body name="3_Neck" pos="0.0000 0.4954 1.0000" user="0.0000 0.5881 1.0000">
            <joint axis="0.0000 0.0000 1.0000" name="3_Neck_z" pos="0.0000 0.4954 1.0000" range="-1800.0 1800.0" type="hinge"/>
            <joint axis="1.0000 0.0000 0.0000" name="3_Neck_x" pos="0.0000 0.4954 1.0000" range="-1800.0 1800.0" type="hinge"/>
            <joint axis="0.0000 1.0000 0.0000" name="3_Neck_y" pos="0.0000 0.4954 1.0000" range="-1800.0 1800.0" type="hinge"/>
            <geom fromto="0.0000 0.4754 1.0000 0.0000 0.5281 1.0000" size="0.0300" type="capsule"/>
            <body name="3_Head" pos="0.0000 0.5881 1.0000" user="0.0000 0.7031 1.0000">
              <geom pos="0.0000 0.6401 0.9660" size="0.0750" type="sphere"/>
              <joint axis="0.0000 0.0000 1.0000" name="3_Head_z" pos="0.0000 0.5881 1.0000" range="-1800.0 1800.0" type="hinge"/>
              <joint axis="1.0000 0.0000 0.0000" name="3_Head_x" pos="0.0000 0.5881 1.0000" range="-1800.0 1800.0" type="hinge"/>
              <joint axis="0.0000 1.0000 0.0000" name="3_Head_y" pos="0.0000 0.5881 1.0000" range="-1800.0 1800.0" type="hinge"/>
            </body>
          </body>
          <body name="3_LeftShoulder" pos="0.0000 0.4954 1.0000" user="0.0000 0.6203 1.0000">
            <joint axis="0.0000 0.0000 1.0000" name="3_LeftShoulder_z" pos="0.0000 0.4954 1.0000" range="-1800.0 1800.0" type="hinge"/>
            <joint axis="1.0000 0.0000 0.0000" name="3_LeftShoulder_x" pos="0.0000 0.4954 1.0000" range="-1800.0 1800.0" type="hinge"/>
            <joint axis="0.0000 1.0000 0.0000" name="3_LeftShoulder_y" pos="0.0000 0.4954 1.0000" range="-1800.0 1800.0" type="hinge"/>
            <geom fromto="0.0000 0.5154 1.0000 0.0000 0.6003 1.0000" size="0.0400" type="capsule"/>
            <body name="3_LeftArm" pos="0.0000 0.6203 1.0000" user="0.0000 0.8800 1.0000">
              <joint axis="0.0000 0.0000 1.0000" name="3_LeftArm_z" pos="0.0000 0.6203 1.0000" range="-1800.0 1800.0" type="hinge"/>
              <joint axis="1.0000 0.0000 0.0000" name="3_LeftArm_x" pos="0.0000 0.6203 1.0000" range="-1800.0 1800.0" type="hinge"/>
              <joint axis="0.0000 1.0000 0.0000" name="3_LeftArm_y" pos="0.0000 0.6203 1.0000" range="-1800.0 1800.0" type="hinge"/>
              <geom fromto="0.0000 0.6403 1.0000 0.0000 0.8600 1.0000" size="0.0340" type="capsule"/>
              <body name="3_LeftForeArm" pos="0.0000 0.8800 1.0000" user="0.0000 1.1256 1.0000">
                <joint axis="1.0000 0.0000 0.0000" name="3_LeftForeArm_x" pos="0.0000 0.8800 1.0000" range="-1800.0 1800.0" type="hinge"/>
                <geom fromto="0.0000 0.9000 1.0000 0.0000 1.1056 1.0000" size="0.0300" type="capsule"/>
                <body name="3_LeftHand" pos="0.0000 1.1256 1.0000" user="0.0000 1.1256 1.0000">
                  <geom pos="0.0000 1.1256 1.0000" size="0.0400" type="sphere"/>
                  <joint axis="0.0000 0.0000 1.0000" name="3_LeftHand_z" pos="0.0000 1.1256 1.0000" range="-1800.0 1800.0" type="hinge"/>
                  <joint axis="1.0000 0.0000 0.0000" name="3_LeftHand_x" pos="0.0000 1.1256 1.0000" range="-1800.0 1800.0" type="hinge"/>
                  <joint axis="0.0000 1.0000 0.0000" name="3_LeftHand_y" pos="0.0000 1.1256 1.0000" range="-1800.0 1800.0" type="hinge"/>
                </body>
              </body>
            </body>
          </body>
          <body name="3_RightShoulder" pos="-0.0000 0.4954 1.0000" user="0.0000 0.6203 1.0000">
            <joint axis="0.0000 0.0000 1.0000" name="3_RightShoulder_z" pos="0.0000 0.4954 1.0000" range="-1800.0 1800.0" type="hinge"/>
            <joint axis="1.0000 0.0000 0.0000" name="3_RightShoulder_x" pos="0.0000 0.4954 1.0000" range="-1800.0 1800.0" type="hinge"/>
            <joint axis="0.0000 1.0000 0.0000" name="3_RightShoulder_y" pos="0.0000 0.4954 1.0000" range="-1800.0 1800.0" type="hinge"/>
            <geom fromto="-0.0000 0.5154 1.0000 -0.0000 0.6003 1.0000" size="0.0400" type="capsule"/>
            <body name="3_RightArm" pos="-0.0000 0.6203 1.0000" user="0.0000 0.8800 1.0000">
              <joint axis="0.0000 0.0000 1.0000" name="3_RightArm_z" pos="0.0000 0.6203 1.0000" range="-1800.0 1800.0" type="hinge"/>
              <joint axis="1.0000 0.0000 0.0000" name="3_RightArm_x" pos="0.0000 0.6203 1.0000" range="-1800.0 1800.0" type="hinge"/>
              <joint axis="0.0000 1.0000 0.0000" name="3_RightArm_y" pos="0.0000 0.6203 1.0000" range="-1800.0 1800.0" type="hinge"/>
              <geom fromto="-0.0000 0.6403 1.0000 -0.0000 0.8600 1.0000" size="0.0340" type="capsule"/>
              <body name="3_RightForeArm" pos="-0.0000 0.8800 1.0000" user="0.0000 1.1256 1.0000">
                <joint axis="1.0000 0.0000 0.0000" name="3_RightForeArm_x" pos="0.0000 0.8800 1.0000" range="-1800.0 1800.0" type="hinge"/>
                <geom fromto="-0.0000 0.9000 1.0000 -0.0000 1.1056 1.0000" size="0.0300" type="capsule"/>
                <body name="3_RightHand" pos="-0.0000 1.1256 1.0000" user="0.0000 1.1256 1.0000">
                  <geom pos="-0.0000 1.1256 1.0000" size="0.0400" type="sphere"/>
                  <joint axis="0.0000 0.0000 1.0000" name="3_RightHand_z" pos="0.0000 1.1256 1.0000" range="-1800.0 1800.0" type="hinge"/>
                  <joint axis="1.0000 0.0000 0.0000" name="3_RightHand_x" pos="0.0000 1.1256 1.0000" range="-1800.0 1800.0" type="hinge"/>
                  <joint axis="0.0000 1.0000 0.0000" name="3_RightHand_y" pos="0.0000 1.1256 1.0000" range="-1800.0 1800.0" type="hinge"/>
                </body>
              </body>
            </body>
          </body>
        </body>
      </body>
    </body>
    <body name="4_Hips" pos="0.0000 0.0000 1.0000" user="0.0000 0.0003 1.0000">
      <joint armature="0" damping="0" limited="false" name="4_Hips" pos="0.0000 0.0000 1.0000" stiffness="0" type="free"/>
      <geom pos="0.0000 0.0000 0.9780" size="0.0950" type="sphere"/>
      <body name="4_RightUpLeg" pos="-0.1272 0.0000 1.0000" user="-0.1272 -0.4343 1.0000">
        <joint axis="0.0000 0.0000 1.0000" name="4_RightUpLeg_z" pos="-0.1272 0.0000 1.0000" range="-1800.0 1800.0" type="hinge"/>
        <joint axis="1.0000 0.0000 0.0000" name="4_RightUpLeg_x" pos="-0.1272 0.0000 1.0000" range="-1800.0 1800.0" type="hinge"/>
        <joint axis="0.0000 1.0000 0.0000" name="4_RightUpLeg_y" pos="-0.1272 0.0000 1.0000" range="-1800.0 1800.0" type="hinge"/>
        <geom contype="1" conaffinity="1" fromto="-0.1272 -0.0200 1.0000 -0.1272 -0.4143 1.0000" size="0.0490" type="capsule"/>
        <body name="4_RightLeg" pos="-0.1272 -0.4343 1.0000" user="-0.1272 -0.8831 1.0000">
          <joint axis="1.0000 0.0000 0.0000" name="4_RightLeg_x" pos="-0.1272 -0.4343 1.0000" range="-1800.0 1800.0" type="hinge"/>
          <geom contype="1" conaffinity="1" fromto="-0.1272 -0.4543 1.0000 -0.1272 -0.8631 1.0000" size="0.0400" type="capsule"/>
          <body name="4_RightFoot" pos="-0.1272 -0.8831 1.0000" user="-0.1272 -0.8831 1.1515">
            <geom contype="1" conaffinity="1" pos="-0.1272 -0.8831 1.0477" size="0.0620 0.0300 0.1000" quat="0.9952 -0.0871 0.0038 -0.0435" type="box"/>
            <joint axis="0.0000 0.0000 1.0000" name="4_RightFoot_z" pos="-0.1272 -0.8831 1.0000" range="-1800.0 1800.0" type="hinge"/>
            <joint axis="1.0000 0.0000 0.0000" name="4_RightFoot_x" pos="-0.1272 -0.8831 1.0000" range="-1800.0 1800.0" type="hinge"/>
            <joint axis="0.0000 1.0000 0.0000" name="4_RightFoot_y" pos="-0.1272 -0.8831 1.0000" range="-1800.0 1800.0" type="hinge"/>
          </body>
        </body>
      </body>
      <body name="4_LeftUpLeg" pos="0.1272 0.0000 1.0000" user="0.1272 -0.4343 1.0000">
        <joint axis="0.0000 0.0000 1.0000" name="4_LeftUpLeg_z" pos="0.1272 0.0000 1.0000" range="-1800.0 1800.0" type="hinge"/>
        <joint axis="1.0000 0.0000 0.0000" name="4_LeftUpLeg_x" pos="0.1272 0.0000 1.0000" range="-1800.0 1800.0" type="hinge"/>
        <joint axis="0.0000 1.0000 0.0000" name="4_LeftUpLeg_y" pos="0.1272 0.0000 1.0000" range="-1800.0 1800.0" type="hinge"/>
        <geom contype="2" conaffinity="2" fromto="0.1272 -0.0200 1.0000 0.1272 -0.4143 1.0000" size="0.0490" type="capsule"/>
        <body name="4_LeftLeg" pos="0.1272 -0.4343 1.0000" user="0.1272 -0.8831 1.0000">
          <joint axis="1.0000 0.0000 0.0000" name="4_LeftLeg_x" pos="0.1272 -0.4343 1.0000" range="-1800.0 1800.0" type="hinge"/>
          <geom contype="2" conaffinity="2" fromto="0.1272 -0.4543 1.0000 0.1272 -0.8631 1.0000" size="0.0400" type="capsule"/>
          <body name="4_LeftFoot" pos="0.1272 -0.8831 1.0000" user="0.1272 -0.8831 1.1515">
            <geom contype="2" conaffinity="2" pos="0.1272 -0.8831 1.0477" size="0.0620 0.0300 0.1000" quat="0.9952 -0.0871 -0.0038 0.0435" type="box"/>
            <joint axis="0.0000 0.0000 1.0000" name="4_LeftFoot_z" pos="0.1272 -0.8831 1.0000" range="-1800.0 1800.0" type="hinge"/>
            <joint axis="1.0000 0.0000 0.0000" name="4_LeftFoot_x" pos="0.1272 -0.8831 1.0000" range="-1800.0 1800.0" type="hinge"/>
            <joint axis="0.0000 1.0000 0.0000" name="4_LeftFoot_y" pos="0.1272 -0.8831 1.0000" range="-1800.0 1800.0" type="hinge"/>
          </body>
        </body>
      </body>
      <body name="4_Spine" pos="0.0000 0.0010 1.0000" user="0.0000 0.2469 1.0000">
        <geom fromto="-0.0700 0.1240 1.0000 0.0700 0.1240 1.0000" size="0.0450" type="capsule"/>
        <geom fromto="-0.0700 0.2160 1.0000 0.0700 0.2160 1.0000" size="0.0450" type="capsule"/>
        <joint axis="0.0000 0.0000 1.0000" name="4_Spine_z" pos="0.0000 0.0010 1.0000" range="-1800.0 1800.0" type="hinge"/>
        <joint axis="1.0000 0.0000 0.0000" name="4_Spine_x" pos="0.0000 0.0010 1.0000" range="-1800.0 1800.0" type="hinge"/>
        <joint axis="0.0000 1.0000 0.0000" name="4_Spine_y" pos="0.0000 0.0010 1.0000" range="-1800.0 1800.0" type="hinge"/>
        <body name="4_Spine1" pos="0.0000 0.2469 1.0000" user="0.0000 0.4954 1.0000">
          <geom fromto="-0.0700 0.3091 1.0000 0.0700 0.3091 1.0000" size="0.0450" type="capsule"/>
          <geom fromto="-0.0700 0.4011 1.0000 0.0700 0.4011 1.0000" size="0.0450" type="capsule"/>
          <joint axis="0.0000 0.0000 1.0000" name="4_Spine1_z" pos="0.0000 0.2469 1.0000" range="-1800.0 1800.0" type="hinge"/>
          <joint axis="1.0000 0.0000 0.0000" name="4_Spine1_x" pos="0.0000 0.2469 1.0000" range="-1800.0 1800.0" type="hinge"/>
          <joint axis="0.0000 1.0000 0.0000" name="4_Spine1_y" pos="0.0000 0.2469 1.0000" range="-1800.0 1800.0" type="hinge"/>
          <body name="4_Neck" pos="0.0000 0.4954 1.0000" user="0.0000 0.5881 1.0000">
            <joint axis="0.0000 0.0000 1.0000" name="4_Neck_z" pos="0.0000 0.4954 1.0000" range="-1800.0 1800.0" type="hinge"/>
            <joint axis="1.0000 0.0000 0.0000" name="4_Neck_x" pos="0.0000 0.4954 1.0000" range="-1800.0 1800.0" type="hinge"/>
            <joint axis="0.0000 1.0000 0.0000" name="4_Neck_y" pos="0.0000 0.4954 1.0000" range="-1800.0 1800.0" type="hinge"/>
            <geom fromto="0.0000 0.4754 1.0000 0.0000 0.5281 1.0000" size="0.0300" type="capsule"/>
            <body name="4_Head" pos="0.0000 0.5881 1.0000" user="0.0000 0.7031 1.0000">
              <geom pos="0.0000 0.6401 0.9660" size="0.0750" type="sphere"/>
              <joint axis="0.0000 0.0000 1.0000" name="4_Head_z" pos="0.0000 0.5881 1.0000" range="-1800.0 1800.0" type="hinge"/>
              <joint axis="1.0000 0.0000 0.0000" name="4_Head_x" pos="0.0000 0.5881 1.0000" range="-1800.0 1800.0" type="hinge"/>
              <joint axis="0.0000 1.0000 0.0000" name="4_Head_y" pos="0.0000 0.5881 1.0000" range="-1800.0 1800.0" type="hinge"/>
            </body>
          </body>
          <body name="4_LeftShoulder" pos="0.0000 0.4954 1.0000" user="0.0000 0.6203 1.0000">
            <joint axis="0.0000 0.0000 1.0000" name="4_LeftShoulder_z" pos="0.0000 0.4954 1.0000" range="-1800.0 1800.0" type="hinge"/>
            <joint axis="1.0000 0.0000 0.0000" name="4_LeftShoulder_x" pos="0.0000 0.4954 1.0000" range="-1800.0 1800.0" type="hinge"/>
            <joint axis="0.0000 1.0000 0.0000" name="4_LeftShoulder_y" pos="0.0000 0.4954 1.0000" range="-1800.0 1800.0" type="hinge"/>
            <geom fromto="0.0000 0.5154 1.0000 0.0000 0.6003 1.0000" size="0.0400" type="capsule"/>
            <body name="4_LeftArm" pos="0.0000 0.6203 1.0000" user="0.0000 0.8800 1.0000">
              <joint axis="0.0000 0.0000 1.0000" name="4_LeftArm_z" pos="0.0000 0.6203 1.0000" range="-1800.0 1800.0" type="hinge"/>
              <joint axis="1.0000 0.0000 0.0000" name="4_LeftArm_x" pos="0.0000 0.6203 1.0000" range="-1800.0 1800.0" type="hinge"/>
              <joint axis="0.0000 1.0000 0.0000" name="4_LeftArm_y" pos="0.0000 0.6203 1.0000" range="-1800.0 1800.0" type="hinge"/>
              <geom fromto="0.0000 0.6403 1.0000 0.0000 0.8600 1.0000" size="0.0340" type="capsule"/>
              <body name="4_LeftForeArm" pos="0.0000 0.8800 1.0000" user="0.0000 1.1256 1.0000">
                <joint axis="1.0000 0.0000 0.0000" name="4_LeftForeArm_x" pos="0.0000 0.8800 1.0000" range="-1800.0 1800.0" type="hinge"/>
                <geom fromto="0.0000 0.9000 1.0000 0.0000 1.1056 1.0000" size="0.0300" type="capsule"/>
                <body name="4_LeftHand" pos="0.0000 1.1256 1.0000" user="0.0000 1.1256 1.0000">
                  <geom pos="0.0000 1.1256 1.0000" size="0.0400" type="sphere"/>
                  <joint axis="0.0000 0.0000 1.0000" name="4_LeftHand_z" pos="0.0000 1.1256 1.0000" range="-1800.0 1800.0" type="hinge"/>
                  <joint axis="1.0000 0.0000 0.0000" name="4_LeftHand_x" pos="0.0000 1.1256 1.0000" range="-1800.0 1800.0" type="hinge"/>
                  <joint axis="0.0000 1.0000 0.0000" name="4_LeftHand_y" pos="0.0000 1.1256 1.0000" range="-1800.0 1800.0" type="hinge"/>
                </body>
              </body>
            </body>
          </body>
          <body name="4_RightShoulder" pos="-0.0000 0.4954 1.0000" user="0.0000 0.6203 1.0000">
            <joint axis="0.0000 0.0000 1.0000" name="4_RightShoulder_z" pos="0.0000 0.4954 1.0000" range="-1800.0 1800.0" type="hinge"/>
            <joint axis="1.0000 0.0000 0.0000" name="4_RightShoulder_x" pos="0.0000 0.4954 1.0000" range="-1800.0 1800.0" type="hinge"/>
            <joint axis="0.0000 1.0000 0.0000" name="4_RightShoulder_y" pos="0.0000 0.4954 1.0000" range="-1800.0 1800.0" type="hinge"/>
            <geom fromto="-0.0000 0.5154 1.0000 -0.0000 0.6003 1.0000" size="0.0400" type="capsule"/>
            <body name="4_RightArm" pos="-0.0000 0.6203 1.0000" user="0.0000 0.8800 1.0000">
              <joint axis="0.0000 0.0000 1.0000" name="4_RightArm_z" pos="0.0000 0.6203 1.0000" range="-1800.0 1800.0" type="hinge"/>
              <joint axis="1.0000 0.0000 0.0000" name="4_RightArm_x" pos="0.0000 0.6203 1.0000" range="-1800.0 1800.0" type="hinge"/>
              <joint axis="0.0000 1.0000 0.0000" name="4_RightArm_y" pos="0.0000 0.6203 1.0000" range="-1800.0 1800.0" type="hinge"/>
              <geom fromto="-0.0000 0.6403 1.0000 -0.0000 0.8600 1.0000" size="0.0340" type="capsule"/>
              <body name="4_RightForeArm" pos="-0.0000 0.8800 1.0000" user="0.0000 1.1256 1.0000">
                <joint axis="1.0000 0.0000 0.0000" name="4_RightForeArm_x" pos="0.0000 0.8800 1.0000" range="-1800.0 1800.0" type="hinge"/>
                <geom fromto="-0.0000 0.9000 1.0000 -0.0000 1.1056 1.0000" size="0.0300" type="capsule"/>
                <body name="4_RightHand" pos="-0.0000 1.1256 1.0000" user="0.0000 1.1256 1.0000">
                  <geom pos="-0.0000 1.1256 1.0000" size="0.0400" type="sphere"/>
                  <joint axis="0.0000 0.0000 1.0000" name="4_RightHand_z" pos="0.0000 1.1256 1.0000" range="-1800.0 1800.0" type="hinge"/>
                  <joint axis="1.0000 0.0000 0.0000" name="4_RightHand_x" pos="0.0000 1.1256 1.0000" range="-1800.0 1800.0" type="hinge"/>
                  <joint axis="0.0000 1.0000 0.0000" name="4_RightHand_y" pos="0.0000 1.1256 1.0000" range="-1800.0 1800.0" type="hinge"/>
                </body>
              </body>
            </body>
          </body>
        </body>
      </body>
    </body>
    <body name="5_Hips" pos="0.0000 0.0000 1.0000" user="0.0000 0.0003 1.0000">
      <joint armature="0" damping="0" limited="false" name="5_Hips" pos="0.0000 0.0000 1.0000" stiffness="0" type="free"/>
      <geom pos="0.0000 0.0000 0.9780" size="0.0950" type="sphere"/>
      <body name="5_RightUpLeg" pos="-0.1272 0.0000 1.0000" user="-0.1272 -0.4343 1.0000">
        <joint axis="0.0000 0.0000 1.0000" name="5_RightUpLeg_z" pos="-0.1272 0.0000 1.0000" range="-1800.0 1800.0" type="hinge"/>
        <joint axis="1.0000 0.0000 0.0000" name="5_RightUpLeg_x" pos="-0.1272 0.0000 1.0000" range="-1800.0 1800.0" type="hinge"/>
        <joint axis="0.0000 1.0000 0.0000" name="5_RightUpLeg_y" pos="-0.1272 0.0000 1.0000" range="-1800.0 1800.0" type="hinge"/>
        <geom contype="1" conaffinity="1" fromto="-0.1272 -0.0200 1.0000 -0.1272 -0.4143 1.0000" size="0.0490" type="capsule"/>
        <body name="5_RightLeg" pos="-0.1272 -0.4343 1.0000" user="-0.1272 -0.8831 1.0000">
          <joint axis="1.0000 0.0000 0.0000" name="5_RightLeg_x" pos="-0.1272 -0.4343 1.0000" range="-1800.0 1800.0" type="hinge"/>
          <geom contype="1" conaffinity="1" fromto="-0.1272 -0.4543 1.0000 -0.1272 -0.8631 1.0000" size="0.0400" type="capsule"/>
          <body name="5_RightFoot" pos="-0.1272 -0.8831 1.0000" user="-0.1272 -0.8831 1.1515">
            <geom contype="1" conaffinity="1" pos="-0.1272 -0.8831 1.0477" size="0.0620 0.0300 0.1000" quat="0.9952 -0.0871 0.0038 -0.0435" type="box"/>
            <joint axis="0.0000 0.0000 1.0000" name="5_RightFoot_z" pos="-0.1272 -0.8831 1.0000" range="-1800.0 1800.0" type="hinge"/>
            <joint axis="1.0000 0.0000 0.0000" name="5_RightFoot_x" pos="-0.1272 -0.8831 1.0000" range="-1800.0 1800.0" type="hinge"/>
            <joint axis="0.0000 1.0000 0.0000" name="5_RightFoot_y" pos="-0.1272 -0.8831 1.0000" range="-1800.0 1800.0" type="hinge"/>
          </body>
        </body>
      </body>
      <body name="5_LeftUpLeg" pos="0.1272 0.0000 1.0000" user="0.1272 -0.4343 1.0000">
        <joint axis="0.0000 0.0000 1.0000" name="5_LeftUpLeg_z" pos="0.1272 0.0000 1.0000" range="-1800.0 1800.0" type="hinge"/>
        <joint axis="1.0000 0.0000 0.0000" name="5_LeftUpLeg_x" pos="0.1272 0.0000 1.0000" range="-1800.0 1800.0" type="hinge"/>
        <joint axis="0.0000 1.0000 0.0000" name="5_LeftUpLeg_y" pos="0.1272 0.0000 1.0000" range="-1800.0 1800.0" type="hinge"/>
        <geom contype="2" conaffinity="2" fromto="0.1272 -0.0200 1.0000 0.1272 -0.4143 1.0000" size="0.0490" type="capsule"/>
        <body name="5_LeftLeg" pos="0.1272 -0.4343 1.0000" user="0.1272 -0.8831 1.0000">
          <joint axis="1.0000 0.0000 0.0000" name="5_LeftLeg_x" pos="0.1272 -0.4343 1.0000" range="-1800.0 1800.0" type="hinge"/>
          <geom contype="2" conaffinity="2" fromto="0.1272 -0.4543 1.0000 0.1272 -0.8631 1.0000" size="0.0400" type="capsule"/>
          <body name="5_LeftFoot" pos="0.1272 -0.8831 1.0000" user="0.1272 -0.8831 1.1515">
            <geom contype="2" conaffinity="2" pos="0.1272 -0.8831 1.0477" size="0.0620 0.0300 0.1000" quat="0.9952 -0.0871 -0.0038 0.0435" type="box"/>
            <joint axis="0.0000 0.0000 1.0000" name="5_LeftFoot_z" pos="0.1272 -0.8831 1.0000" range="-1800.0 1800.0" type="hinge"/>
            <joint axis="1.0000 0.0000 0.0000" name="5_LeftFoot_x" pos="0.1272 -0.8831 1.0000" range="-1800.0 1800.0" type="hinge"/>
            <joint axis="0.0000 1.0000 0.0000" name="5_LeftFoot_y" pos="0.1272 -0.8831 1.0000" range="-1800.0 1800.0" type="hinge"/>
          </body>
        </body>
      </body>
      <body name="5_Spine" pos="0.0000 0.0010 1.0000" user="0.0000 0.2469 1.0000">
        <geom fromto="-0.0700 0.1240 1.0000 0.0700 0.1240 1.0000" size="0.0450" type="capsule"/>
        <geom fromto="-0.0700 0.2160 1.0000 0.0700 0.2160 1.0000" size="0.0450" type="capsule"/>
        <joint axis="0.0000 0.0000 1.0000" name="5_Spine_z" pos="0.0000 0.0010 1.0000" range="-1800.0 1800.0" type="hinge"/>
        <joint axis="1.0000 0.0000 0.0000" name="5_Spine_x" pos="0.0000 0.0010 1.0000" range="-1800.0 1800.0" type="hinge"/>
        <joint axis="0.0000 1.0000 0.0000" name="5_Spine_y" pos="0.0000 0.0010 1.0000" range="-1800.0 1800.0" type="hinge"/>
        <body name="5_Spine1" pos="0.0000 0.2469 1.0000" user="0.0000 0.4954 1.0000">
          <geom fromto="-0.0700 0.3091 1.0000 0.0700 0.3091 1.0000" size="0.0450" type="capsule"/>
          <geom fromto="-0.0700 0.4011 1.0000 0.0700 0.4011 1.0000" size="0.0450" type="capsule"/>
          <joint axis="0.0000 0.0000 1.0000" name="5_Spine1_z" pos="0.0000 0.2469 1.0000" range="-1800.0 1800.0" type="hinge"/>
          <joint axis="1.0000 0.0000 0.0000" name="5_Spine1_x" pos="0.0000 0.2469 1.0000" range="-1800.0 1800.0" type="hinge"/>
          <joint axis="0.0000 1.0000 0.0000" name="5_Spine1_y" pos="0.0000 0.2469 1.0000" range="-1800.0 1800.0" type="hinge"/>
          <body name="5_Neck" pos="0.0000 0.4954 1.0000" user="0.0000 0.5881 1.0000">
            <joint axis="0.0000 0.0000 1.0000" name="5_Neck_z" pos="0.0000 0.4954 1.0000" range="-1800.0 1800.0" type="hinge"/>
            <joint axis="1.0000 0.0000 0.0000" name="5_Neck_x" pos="0.0000 0.4954 1.0000" range="-1800.0 1800.0" type="hinge"/>
            <joint axis="0.0000 1.0000 0.0000" name="5_Neck_y" pos="0.0000 0.4954 1.0000" range="-1800.0 1800.0" type="hinge"/>
            <geom fromto="0.0000 0.4754 1.0000 0.0000 0.5281 1.0000" size="0.0300" type="capsule"/>
            <body name="5_Head" pos="0.0000 0.5881 1.0000" user="0.0000 0.7031 1.0000">
              <geom pos="0.0000 0.6401 0.9660" size="0.0750" type="sphere"/>
              <joint axis="0.0000 0.0000 1.0000" name="5_Head_z" pos="0.0000 0.5881 1.0000" range="-1800.0 1800.0" type="hinge"/>
              <joint axis="1.0000 0.0000 0.0000" name="5_Head_x" pos="0.0000 0.5881 1.0000" range="-1800.0 1800.0" type="hinge"/>
              <joint axis="0.0000 1.0000 0.0000" name="5_Head_y" pos="0.0000 0.5881 1.0000" range="-1800.0 1800.0" type="hinge"/>
            </body>
          </body>
          <body name="5_LeftShoulder" pos="0.0000 0.4954 1.0000" user="0.0000 0.6203 1.0000">
            <joint axis="0.0000 0.0000 1.0000" name="5_LeftShoulder_z" pos="0.0000 0.4954 1.0000" range="-1800.0 1800.0" type="hinge"/>
            <joint axis="1.0000 0.0000 0.0000" name="5_LeftShoulder_x" pos="0.0000 0.4954 1.0000" range="-1800.0 1800.0" type="hinge"/>
            <joint axis="0.0000 1.0000 0.0000" name="5_LeftShoulder_y" pos="0.0000 0.4954 1.0000" range="-1800.0 1800.0" type="hinge"/>
            <geom fromto="0.0000 0.5154 1.0000 0.0000 0.6003 1.0000" size="0.0400" type="capsule"/>
            <body name="5_LeftArm" pos="0.0000 0.6203 1.0000" user="0.0000 0.8800 1.0000">
              <joint axis="0.0000 0.0000 1.0000" name="5_LeftArm_z" pos="0.0000 0.6203 1.0000" range="-1800.0 1800.0" type="hinge"/>
              <joint axis="1.0000 0.0000 0.0000" name="5_LeftArm_x" pos="0.0000 0.6203 1.0000" range="-1800.0 1800.0" type="hinge"/>
              <joint axis="0.0000 1.0000 0.0000" name="5_LeftArm_y" pos="0.0000 0.6203 1.0000" range="-1800.0 1800.0" type="hinge"/>
              <geom fromto="0.0000 0.6403 1.0000 0.0000 0.8600 1.0000" size="0.0340" type="capsule"/>
              <body name="5_LeftForeArm" pos="0.0000 0.8800 1.0000" user="0.0000 1.1256 1.0000">
                <joint axis="1.0000 0.0000 0.0000" name="5_LeftForeArm_x" pos="0.0000 0.8800 1.0000" range="-1800.0 1800.0" type="hinge"/>
                <geom fromto="0.0000 0.9000 1.0000 0.0000 1.1056 1.0000" size="0.0300" type="capsule"/>
                <body name="5_LeftHand" pos="0.0000 1.1256 1.0000" user="0.0000 1.1256 1.0000">
                  <geom pos="0.0000 1.1256 1.0000" size="0.0400" type="sphere"/>
                  <joint axis="0.0000 0.0000 1.0000" name="5_LeftHand_z" pos="0.0000 1.1256 1.0000" range="-1800.0 1800.0" type="hinge"/>
                  <joint axis="1.0000 0.0000 0.0000" name="5_LeftHand_x" pos="0.0000 1.1256 1.0000" range="-1800.0 1800.0" type="hinge"/>
                  <joint axis="0.0000 1.0000 0.0000" name="5_LeftHand_y" pos="0.0000 1.1256 1.0000" range="-1800.0 1800.0" type="hinge"/>
                </body>
              </body>
            </body>
          </body>
          <body name="5_RightShoulder" pos="-0.0000 0.4954 1.0000" user="0.0000 0.6203 1.0000">
            <joint axis="0.0000 0.0000 1.0000" name="5_RightShoulder_z" pos="0.0000 0.4954 1.0000" range="-1800.0 1800.0" type="hinge"/>
            <joint axis="1.0000 0.0000 0.0000" name="5_RightShoulder_x" pos="0.0000 0.4954 1.0000" range="-1800.0 1800.0" type="hinge"/>
            <joint axis="0.0000 1.0000 0.0000" name="5_RightShoulder_y" pos="0.0000 0.4954 1.0000" range="-1800.0 1800.0" type="hinge"/>
            <geom fromto="-0.0000 0.5154 1.0000 -0.0000 0.6003 1.0000" size="0.0400" type="capsule"/>
            <body name="5_RightArm" pos="-0.0000 0.6203 1.0000" user="0.0000 0.8800 1.0000">
              <joint axis="0.0000 0.0000 1.0000" name="5_RightArm_z" pos="0.0000 0.6203 1.0000" range="-1800.0 1800.0" type="hinge"/>
              <joint axis="1.0000 0.0000 0.0000" name="5_RightArm_x" pos="0.0000 0.6203 1.0000" range="-1800.0 1800.0" type="hinge"/>
              <joint axis="0.0000 1.0000 0.0000" name="5_RightArm_y" pos="0.0000 0.6203 1.0000" range="-1800.0 1800.0" type="hinge"/>
              <geom fromto="-0.0000 0.6403 1.0000 -0.0000 0.8600 1.0000" size="0.0340" type="capsule"/>
              <body name="5_RightForeArm" pos="-0.0000 0.8800 1.0000" user="0.0000 1.1256 1.0000">
                <joint axis="1.0000 0.0000 0.0000" name="5_RightForeArm_x" pos="0.0000 0.8800 1.0000" range="-1800.0 1800.0" type="hinge"/>
                <geom fromto="-0.0000 0.9000 1.0000 -0.0000 1.1056 1.0000" size="0.0300" type="capsule"/>
                <body name="5_RightHand" pos="-0.0000 1.1256 1.0000" user="0.0000 1.1256 1.0000">
                  <geom pos="-0.0000 1.1256 1.0000" size="0.0400" type="sphere"/>
                  <joint axis="0.0000 0.0000 1.0000" name="5_RightHand_z" pos="0.0000 1.1256 1.0000" range="-1800.0 1800.0" type="hinge"/>
                  <joint axis="1.0000 0.0000 0.0000" name="5_RightHand_x" pos="0.0000 1.1256 1.0000" range="-1800.0 1800.0" type="hinge"/>
                  <joint axis="0.0000 1.0000 0.0000" name="5_RightHand_y" pos="0.0000 1.1256 1.0000" range="-1800.0 1800.0" type="hinge"/>
                </body>
              </body>
            </body>
          </body>
        </body>
      </body>
    </body>
    <body name="6_Hips" pos="0.0000 0.0000 1.0000" user="0.0000 0.0003 1.0000">
      <joint armature="0" damping="0" limited="false" name="6_Hips" pos="0.0000 0.0000 1.0000" stiffness="0" type="free"/>
      <geom pos="0.0000 0.0000 0.9780" size="0.0950" type="sphere"/>
      <body name="6_RightUpLeg" pos="-0.1272 0.0000 1.0000" user="-0.1272 -0.4343 1.0000">
        <joint axis="0.0000 0.0000 1.0000" name="6_RightUpLeg_z" pos="-0.1272 0.0000 1.0000" range="-1800.0 1800.0" type="hinge"/>
        <joint axis="1.0000 0.0000 0.0000" name="6_RightUpLeg_x" pos="-0.1272 0.0000 1.0000" range="-1800.0 1800.0" type="hinge"/>
        <joint axis="0.0000 1.0000 0.0000" name="6_RightUpLeg_y" pos="-0.1272 0.0000 1.0000" range="-1800.0 1800.0" type="hinge"/>
        <geom contype="1" conaffinity="1" fromto="-0.1272 -0.0200 1.0000 -0.1272 -0.4143 1.0000" size="0.0490" type="capsule"/>
        <body name="6_RightLeg" pos="-0.1272 -0.4343 1.0000" user="-0.1272 -0.8831 1.0000">
          <joint axis="1.0000 0.0000 0.0000" name="6_RightLeg_x" pos="-0.1272 -0.4343 1.0000" range="-1800.0 1800.0" type="hinge"/>
          <geom contype="1" conaffinity="1" fromto="-0.1272 -0.4543 1.0000 -0.1272 -0.8631 1.0000" size="0.0400" type="capsule"/>
          <body name="6_RightFoot" pos="-0.1272 -0.8831 1.0000" user="-0.1272 -0.8831 1.1515">
            <geom contype="1" conaffinity="1" pos="-0.1272 -0.8831 1.0477" size="0.0620 0.0300 0.1000" quat="0.9952 -0.0871 0.0038 -0.0435" type="box"/>
            <joint axis="0.0000 0.0000 1.0000" name="6_RightFoot_z" pos="-0.1272 -0.8831 1.0000" range="-1800.0 1800.0" type="hinge"/>
            <joint axis="1.0000 0.0000 0.0000" name="6_RightFoot_x" pos="-0.1272 -0.8831 1.0000" range="-1800.0 1800.0" type="hinge"/>
            <joint axis="0.0000 1.0000 0.0000" name="6_RightFoot_y" pos="-0.1272 -0.8831 1.0000" range="-1800.0 1800.0" type="hinge"/>
          </body>
        </body>
      </body>
      <body name="6_LeftUpLeg" pos="0.1272 0.0000 1.0000" user="0.1272 -0.4343 1.0000">
        <joint axis="0.0000 0.0000 1.0000" name="6_LeftUpLeg_z" pos="0.1272 0.0000 1.0000" range="-1800.0 1800.0" type="hinge"/>
        <joint axis="1.0000 0.0000 0.0000" name="6_LeftUpLeg_x" pos="0.1272 0.0000 1.0000" range="-1800.0 1800.0" type="hinge"/>
        <joint axis="0.0000 1.0000 0.0000" name="6_LeftUpLeg_y" pos="0.1272 0.0000 1.0000" range="-1800.0 1800.0" type="hinge"/>
        <geom contype="2" conaffinity="2" fromto="0.1272 -0.0200 1.0000 0.1272 -0.4143 1.0000" size="0.0490" type="capsule"/>
        <body name="6_LeftLeg" pos="0.1272 -0.4343 1.0000" user="0.1272 -0.8831 1.0000">
          <joint axis="1.0000 0.0000 0.0000" name="6_LeftLeg_x" pos="0.1272 -0.4343 1.0000" range="-1800.0 1800.0" type="hinge"/>
          <geom contype="2" conaffinity="2" fromto="0.1272 -0.4543 1.0000 0.1272 -0.8631 1.0000" size="0.0400" type="capsule"/>
          <body name="6_LeftFoot" pos="0.1272 -0.8831 1.0000" user="0.1272 -0.8831 1.1515">
            <geom contype="2" conaffinity="2" pos="0.1272 -0.8831 1.0477" size="0.0620 0.0300 0.1000" quat="0.9952 -0.0871 -0.0038 0.0435" type="box"/>
            <joint axis="0.0000 0.0000 1.0000" name="6_LeftFoot_z" pos="0.1272 -0.8831 1.0000" range="-1800.0 1800.0" type="hinge"/>
            <joint axis="1.0000 0.0000 0.0000" name="6_LeftFoot_x" pos="0.1272 -0.8831 1.0000" range="-1800.0 1800.0" type="hinge"/>
            <joint axis="0.0000 1.0000 0.0000" name="6_LeftFoot_y" pos="0.1272 -0.8831 1.0000" range="-1800.0 1800.0" type="hinge"/>
          </body>
        </body>
      </body>
      <body name="6_Spine" pos="0.0000 0.0010 1.0000" user="0.0000 0.2469 1.0000">
        <geom fromto="-0.0700 0.1240 1.0000 0.0700 0.1240 1.0000" size="0.0450" type="capsule"/>
        <geom fromto="-0.0700 0.2160 1.0000 0.0700 0.2160 1.0000" size="0.0450" type="capsule"/>
        <joint axis="0.0000 0.0000 1.0000" name="6_Spine_z" pos="0.0000 0.0010 1.0000" range="-1800.0 1800.0" type="hinge"/>
        <joint axis="1.0000 0.0000 0.0000" name="6_Spine_x" pos="0.0000 0.0010 1.0000" range="-1800.0 1800.0" type="hinge"/>
        <joint axis="0.0000 1.0000 0.0000" name="6_Spine_y" pos="0.0000 0.0010 1.0000" range="-1800.0 1800.0" type="hinge"/>
        <body name="6_Spine1" pos="0.0000 0.2469 1.0000" user="0.0000 0.4954 1.0000">
          <geom fromto="-0.0700 0.3091 1.0000 0.0700 0.3091 1.0000" size="0.0450" type="capsule"/>
          <geom fromto="-0.0700 0.4011 1.0000 0.0700 0.4011 1.0000" size="0.0450" type="capsule"/>
          <joint axis="0.0000 0.0000 1.0000" name="6_Spine1_z" pos="0.0000 0.2469 1.0000" range="-1800.0 1800.0" type="hinge"/>
          <joint axis="1.0000 0.0000 0.0000" name="6_Spine1_x" pos="0.0000 0.2469 1.0000" range="-1800.0 1800.0" type="hinge"/>
          <joint axis="0.0000 1.0000 0.0000" name="6_Spine1_y" pos="0.0000 0.2469 1.0000" range="-1800.0 1800.0" type="hinge"/>
          <body name="6_Neck" pos="0.0000 0.4954 1.0000" user="0.0000 0.5881 1.0000">
            <joint axis="0.0000 0.0000 1.0000" name="6_Neck_z" pos="0.0000 0.4954 1.0000" range="-1800.0 1800.0" type="hinge"/>
            <joint axis="1.0000 0.0000 0.0000" name="6_Neck_x" pos="0.0000 0.4954 1.0000" range="-1800.0 1800.0" type="hinge"/>
            <joint axis="0.0000 1.0000 0.0000" name="6_Neck_y" pos="0.0000 0.4954 1.0000" range="-1800.0 1800.0" type="hinge"/>
            <geom fromto="0.0000 0.4754 1.0000 0.0000 0.5281 1.0000" size="0.0300" type="capsule"/>
            <body name="6_Head" pos="0.0000 0.5881 1.0000" user="0.0000 0.7031 1.0000">
              <geom pos="0.0000 0.6401 0.9660" size="0.0750" type="sphere"/>
              <joint axis="0.0000 0.0000 1.0000" name="6_Head_z" pos="0.0000 0.5881 1.0000" range="-1800.0 1800.0" type="hinge"/>
              <joint axis="1.0000 0.0000 0.0000" name="6_Head_x" pos="0.0000 0.5881 1.0000" range="-1800.0 1800.0" type="hinge"/>
              <joint axis="0.0000 1.0000 0.0000" name="6_Head_y" pos="0.0000 0.5881 1.0000" range="-1800.0 1800.0" type="hinge"/>
            </body>
          </body>
          <body name="6_LeftShoulder" pos="0.0000 0.4954 1.0000" user="0.0000 0.6203 1.0000">
            <joint axis="0.0000 0.0000 1.0000" name="6_LeftShoulder_z" pos="0.0000 0.4954 1.0000" range="-1800.0 1800.0" type="hinge"/>
            <joint axis="1.0000 0.0000 0.0000" name="6_LeftShoulder_x" pos="0.0000 0.4954 1.0000" range="-1800.0 1800.0" type="hinge"/>
            <joint axis="0.0000 1.0000 0.0000" name="6_LeftShoulder_y" pos="0.0000 0.4954 1.0000" range="-1800.0 1800.0" type="hinge"/>
            <geom fromto="0.0000 0.5154 1.0000 0.0000 0.6003 1.0000" size="0.0400" type="capsule"/>
            <body name="6_LeftArm" pos="0.0000 0.6203 1.0000" user="0.0000 0.8800 1.0000">
              <joint axis="0.0000 0.0000 1.0000" name="6_LeftArm_z" pos="0.0000 0.6203 1.0000" range="-1800.0 1800.0" type="hinge"/>
              <joint axis="1.0000 0.0000 0.0000" name="6_LeftArm_x" pos="0.0000 0.6203 1.0000" range="-1800.0 1800.0" type="hinge"/>
              <joint axis="0.0000 1.0000 0.0000" name="6_LeftArm_y" pos="0.0000 0.6203 1.0000" range="-1800.0 1800.0" type="hinge"/>
              <geom fromto="0.0000 0.6403 1.0000 0.0000 0.8600 1.0000" size="0.0340" type="capsule"/>
              <body name="6_LeftForeArm" pos="0.0000 0.8800 1.0000" user="0.0000 1.1256 1.0000">
                <joint axis="1.0000 0.0000 0.0000" name="6_LeftForeArm_x" pos="0.0000 0.8800 1.0000" range="-1800.0 1800.0" type="hinge"/>
                <geom fromto="0.0000 0.9000 1.0000 0.0000 1.1056 1.0000" size="0.0300" type="capsule"/>
                <body name="6_LeftHand" pos="0.0000 1.1256 1.0000" user="0.0000 1.1256 1.0000">
                  <geom pos="0.0000 1.1256 1.0000" size="0.0400" type="sphere"/>
                  <joint axis="0.0000 0.0000 1.0000" name="6_LeftHand_z" pos="0.0000 1.1256 1.0000" range="-1800.0 1800.0" type="hinge"/>
                  <joint axis="1.0000 0.0000 0.0000" name="6_LeftHand_x" pos="0.0000 1.1256 1.0000" range="-1800.0 1800.0" type="hinge"/>
                  <joint axis="0.0000 1.0000 0.0000" name="6_LeftHand_y" pos="0.0000 1.1256 1.0000" range="-1800.0 1800.0" type="hinge"/>
                </body>
              </body>
            </body>
          </body>
          <body name="6_RightShoulder" pos="-0.0000 0.4954 1.0000" user="0.0000 0.6203 1.0000">
            <joint axis="0.0000 0.0000 1.0000" name="6_RightShoulder_z" pos="0.0000 0.4954 1.0000" range="-1800.0 1800.0" type="hinge"/>
            <joint axis="1.0000 0.0000 0.0000" name="6_RightShoulder_x" pos="0.0000 0.4954 1.0000" range="-1800.0 1800.0" type="hinge"/>
            <joint axis="0.0000 1.0000 0.0000" name="6_RightShoulder_y" pos="0.0000 0.4954 1.0000" range="-1800.0 1800.0" type="hinge"/>
            <geom fromto="-0.0000 0.5154 1.0000 -0.0000 0.6003 1.0000" size="0.0400" type="capsule"/>
            <body name="6_RightArm" pos="-0.0000 0.6203 1.0000" user="0.0000 0.8800 1.0000">
              <joint axis="0.0000 0.0000 1.0000" name="6_RightArm_z" pos="0.0000 0.6203 1.0000" range="-1800.0 1800.0" type="hinge"/>
              <joint axis="1.0000 0.0000 0.0000" name="6_RightArm_x" pos="0.0000 0.6203 1.0000" range="-1800.0 1800.0" type="hinge"/>
              <joint axis="0.0000 1.0000 0.0000" name="6_RightArm_y" pos="0.0000 0.6203 1.0000" range="-1800.0 1800.0" type="hinge"/>
              <geom fromto="-0.0000 0.6403 1.0000 -0.0000 0.8600 1.0000" size="0.0340" type="capsule"/>
              <body name="6_RightForeArm" pos="-0.0000 0.8800 1.0000" user="0.0000 1.1256 1.0000">
                <joint axis="1.0000 0.0000 0.0000" name="6_RightForeArm_x" pos="0.0000 0.8800 1.0000" range="-1800.0 1800.0" type="hinge"/>
                <geom fromto="-0.0000 0.9000 1.0000 -0.0000 1.1056 1.0000" size="0.0300" type="capsule"/>
                <body name="6_RightHand" pos="-0.0000 1.1256 1.0000" user="0.0000 1.1256 1.0000">
                  <geom pos="-0.0000 1.1256 1.0000" size="0.0400" type="sphere"/>
                  <joint axis="0.0000 0.0000 1.0000" name="6_RightHand_z" pos="0.0000 1.1256 1.0000" range="-1800.0 1800.0" type="hinge"/>
                  <joint axis="1.0000 0.0000 0.0000" name="6_RightHand_x" pos="0.0000 1.1256 1.0000" range="-1800.0 1800.0" type="hinge"/>
                  <joint axis="0.0000 1.0000 0.0000" name="6_RightHand_y" pos="0.0000 1.1256 1.0000" range="-1800.0 1800.0" type="hinge"/>
                </body>
              </body>
            </body>
          </body>
        </body>
      </body>
    </body>
    <body name="7_Hips" pos="0.0000 0.0000 1.0000" user="0.0000 0.0003 1.0000">
      <joint armature="0" damping="0" limited="false" name="7_Hips" pos="0.0000 0.0000 1.0000" stiffness="0" type="free"/>
      <geom pos="0.0000 0.0000 0.9780" size="0.0950" type="sphere"/>
      <body name="7_RightUpLeg" pos="-0.1272 0.0000 1.0000" user="-0.1272 -0.4343 1.0000">
        <joint axis="0.0000 0.0000 1.0000" name="7_RightUpLeg_z" pos="-0.1272 0.0000 1.0000" range="-1800.0 1800.0" type="hinge"/>
        <joint axis="1.0000 0.0000 0.0000" name="7_RightUpLeg_x" pos="-0.1272 0.0000 1.0000" range="-1800.0 1800.0" type="hinge"/>
        <joint axis="0.0000 1.0000 0.0000" name="7_RightUpLeg_y" pos="-0.1272 0.0000 1.0000" range="-1800.0 1800.0" type="hinge"/>
        <geom contype="1" conaffinity="1" fromto="-0.1272 -0.0200 1.0000 -0.1272 -0.4143 1.0000" size="0.0490" type="capsule"/>
        <body name="7_RightLeg" pos="-0.1272 -0.4343 1.0000" user="-0.1272 -0.8831 1.0000">
          <joint axis="1.0000 0.0000 0.0000" name="7_RightLeg_x" pos="-0.1272 -0.4343 1.0000" range="-1800.0 1800.0" type="hinge"/>
          <geom contype="1" conaffinity="1" fromto="-0.1272 -0.4543 1.0000 -0.1272 -0.8631 1.0000" size="0.0400" type="capsule"/>
          <body name="7_RightFoot" pos="-0.1272 -0.8831 1.0000" user="-0.1272 -0.8831 1.1515">
            <geom contype="1" conaffinity="1" pos="-0.1272 -0.8831 1.0477" size="0.0620 0.0300 0.1000" quat="0.9952 -0.0871 0.0038 -0.0435" type="box"/>
            <joint axis="0.0000 0.0000 1.0000" name="7_RightFoot_z" pos="-0.1272 -0.8831 1.0000" range="-1800.0 1800.0" type="hinge"/>
            <joint axis="1.0000 0.0000 0.0000" name="7_RightFoot_x" pos="-0.1272 -0.8831 1.0000" range="-1800.0 1800.0" type="hinge"/>
            <joint axis="0.0000 1.0000 0.0000" name="7_RightFoot_y" pos="-0.1272 -0.8831 1.0000" range="-1800.0 1800.0" type="hinge"/>
          </body>
        </body>
      </body>
      <body name="7_LeftUpLeg" pos="0.1272 0.0000 1.0000" user="0.1272 -0.4343 1.0000">
        <joint axis="0.0000 0.0000 1.0000" name="7_LeftUpLeg_z" pos="0.1272 0.0000 1.0000" range="-1800.0 1800.0" type="hinge"/>
        <joint axis="1.0000 0.0000 0.0000" name="7_LeftUpLeg_x" pos="0.1272 0.0000 1.0000" range="-1800.0 1800.0" type="hinge"/>
        <joint axis="0.0000 1.0000 0.0000" name="7_LeftUpLeg_y" pos="0.1272 0.0000 1.0000" range="-1800.0 1800.0" type="hinge"/>
        <geom contype="2" conaffinity="2" fromto="0.1272 -0.0200 1.0000 0.1272 -0.4143 1.0000" size="0.0490" type="capsule"/>
        <body name="7_LeftLeg" pos="0.1272 -0.4343 1.0000" user="0.1272 -0.8831 1.0000">
          <joint axis="1.0000 0.0000 0.0000" name="7_LeftLeg_x" pos="0.1272 -0.4343 1.0000" range="-1800.0 1800.0" type="hinge"/>
          <geom contype="2" conaffinity="2" fromto="0.1272 -0.4543 1.0000 0.1272 -0.8631 1.0000" size="0.0400" type="capsule"/>
          <body name="7_LeftFoot" pos="0.1272 -0.8831 1.0000" user="0.1272 -0.8831 1.1515">
            <geom contype="2" conaffinity="2" pos="0.1272 -0.8831 1.0477" size="0.0620 0.0300 0.1000" quat="0.9952 -0.0871 -0.0038 0.0435" type="box"/>
            <joint axis="0.0000 0.0000 1.0000" name="7_LeftFoot_z" pos="0.1272 -0.8831 1.0000" range="-1800.0 1800.0" type="hinge"/>
            <joint axis="1.0000 0.0000 0.0000" name="7_LeftFoot_x" pos="0.1272 -0.8831 1.0000" range="-1800.0 1800.0" type="hinge"/>
            <joint axis="0.0000 1.0000 0.0000" name="7_LeftFoot_y" pos="0.1272 -0.8831 1.0000" range="-1800.0 1800.0" type="hinge"/>
          </body>
        </body>
      </body>
      <body name="7_Spine" pos="0.0000 0.0010 1.0000" user="0.0000 0.2469 1.0000">
        <geom fromto="-0.0700 0.1240 1.0000 0.0700 0.1240 1.0000" size="0.0450" type="capsule"/>
        <geom fromto="-0.0700 0.2160 1.0000 0.0700 0.2160 1.0000" size="0.0450" type="capsule"/>
        <joint axis="0.0000 0.0000 1.0000" name="7_Spine_z" pos="0.0000 0.0010 1.0000" range="-1800.0 1800.0" type="hinge"/>
        <joint axis="1.0000 0.0000 0.0000" name="7_Spine_x" pos="0.0000 0.0010 1.0000" range="-1800.0 1800.0" type="hinge"/>
        <joint axis="0.0000 1.0000 0.0000" name="7_Spine_y" pos="0.0000 0.0010 1.0000" range="-1800.0 1800.0" type="hinge"/>
        <body name="7_Spine1" pos="0.0000 0.2469 1.0000" user="0.0000 0.4954 1.0000">
          <geom fromto="-0.0700 0.3091 1.0000 0.0700 0.3091 1.0000" size="0.0450" type="capsule"/>
          <geom fromto="-0.0700 0.4011 1.0000 0.0700 0.4011 1.0000" size="0.0450" type="capsule"/>
          <joint axis="0.0000 0.0000 1.0000" name="7_Spine1_z" pos="0.0000 0.2469 1.0000" range="-1800.0 1800.0" type="hinge"/>
          <joint axis="1.0000 0.0000 0.0000" name="7_Spine1_x" pos="0.0000 0.2469 1.0000" range="-1800.0 1800.0" type="hinge"/>
          <joint axis="0.0000 1.0000 0.0000" name="7_Spine1_y" pos="0.0000 0.2469 1.0000" range="-1800.0 1800.0" type="hinge"/>
          <body name="7_Neck" pos="0.0000 0.4954 1.0000" user="0.0000 0.5881 1.0000">
            <joint axis="0.0000 0.0000 1.0000" name="7_Neck_z" pos="0.0000 0.4954 1.0000" range="-1800.0 1800.0" type="hinge"/>
            <joint axis="1.0000 0.0000 0.0000" name="7_Neck_x" pos="0.0000 0.4954 1.0000" range="-1800.0 1800.0" type="hinge"/>
            <joint axis="0.0000 1.0000 0.0000" name="7_Neck_y" pos="0.0000 0.4954 1.0000" range="-1800.0 1800.0" type="hinge"/>
            <geom fromto="0.0000 0.4754 1.0000 0.0000 0.5281 1.0000" size="0.0300" type="capsule"/>
            <body name="7_Head" pos="0.0000 0.5881 1.0000" user="0.0000 0.7031 1.0000">
              <geom pos="0.0000 0.6401 0.9660" size="0.0750" type="sphere"/>
              <joint axis="0.0000 0.0000 1.0000" name="7_Head_z" pos="0.0000 0.5881 1.0000" range="-1800.0 1800.0" type="hinge"/>
              <joint axis="1.0000 0.0000 0.0000" name="7_Head_x" pos="0.0000 0.5881 1.0000" range="-1800.0 1800.0" type="hinge"/>
              <joint axis="0.0000 1.0000 0.0000" name="7_Head_y" pos="0.0000 0.5881 1.0000" range="-1800.0 1800.0" type="hinge"/>
            </body>
          </body>
          <body name="7_LeftShoulder" pos="0.0000 0.4954 1.0000" user="0.0000 0.6203 1.0000">
            <joint axis="0.0000 0.0000 1.0000" name="7_LeftShoulder_z" pos="0.0000 0.4954 1.0000" range="-1800.0 1800.0" type="hinge"/>
            <joint axis="1.0000 0.0000 0.0000" name="7_LeftShoulder_x" pos="0.0000 0.4954 1.0000" range="-1800.0 1800.0" type="hinge"/>
            <joint axis="0.0000 1.0000 0.0000" name="7_LeftShoulder_y" pos="0.0000 0.4954 1.0000" range="-1800.0 1800.0" type="hinge"/>
            <geom fromto="0.0000 0.5154 1.0000 0.0000 0.6003 1.0000" size="0.0400" type="capsule"/>
            <body name="7_LeftArm" pos="0.0000 0.6203 1.0000" user="0.0000 0.8800 1.0000">
              <joint axis="0.0000 0.0000 1.0000" name="7_LeftArm_z" pos="0.0000 0.6203 1.0000" range="-1800.0 1800.0" type="hinge"/>
              <joint axis="1.0000 0.0000 0.0000" name="7_LeftArm_x" pos="0.0000 0.6203 1.0000" range="-1800.0 1800.0" type="hinge"/>
              <joint axis="0.0000 1.0000 0.0000" name="7_LeftArm_y" pos="0.0000 0.6203 1.0000" range="-1800.0 1800.0" type="hinge"/>
              <geom fromto="0.0000 0.6403 1.0000 0.0000 0.8600 1.0000" size="0.0340" type="capsule"/>
              <body name="7_LeftForeArm" pos="0.0000 0.8800 1.0000" user="0.0000 1.1256 1.0000">
                <joint axis="1.0000 0.0000 0.0000" name="7_LeftForeArm_x" pos="0.0000 0.8800 1.0000" range="-1800.0 1800.0" type="hinge"/>
                <geom fromto="0.0000 0.9000 1.0000 0.0000 1.1056 1.0000" size="0.0300" type="capsule"/>
                <body name="7_LeftHand" pos="0.0000 1.1256 1.0000" user="0.0000 1.1256 1.0000">
                  <geom pos="0.0000 1.1256 1.0000" size="0.0400" type="sphere"/>
                  <joint axis="0.0000 0.0000 1.0000" name="7_LeftHand_z" pos="0.0000 1.1256 1.0000" range="-1800.0 1800.0" type="hinge"/>
                  <joint axis="1.0000 0.0000 0.0000" name="7_LeftHand_x" pos="0.0000 1.1256 1.0000" range="-1800.0 1800.0" type="hinge"/>
                  <joint axis="0.0000 1.0000 0.0000" name="7_LeftHand_y" pos="0.0000 1.1256 1.0000" range="-1800.0 1800.0" type="hinge"/>
                </body>
              </body>
            </body>
          </body>
          <body name="7_RightShoulder" pos="-0.0000 0.4954 1.0000" user="0.0000 0.6203 1.0000">
            <joint axis="0.0000 0.0000 1.0000" name="7_RightShoulder_z" pos="0.0000 0.4954 1.0000" range="-1800.0 1800.0" type="hinge"/>
            <joint axis="1.0000 0.0000 0.0000" name="7_RightShoulder_x" pos="0.0000 0.4954 1.0000" range="-1800.0 1800.0" type="hinge"/>
            <joint axis="0.0000 1.0000 0.0000" name="7_RightShoulder_y" pos="0.0000 0.4954 1.0000" range="-1800.0 1800.0" type="hinge"/>
            <geom fromto="-0.0000 0.5154 1.0000 -0.0000 0.6003 1.0000" size="0.0400" type="capsule"/>
            <body name="7_RightArm" pos="-0.0000 0.6203 1.0000" user="0.0000 0.8800 1.0000">
              <joint axis="0.0000 0.0000 1.0000" name="7_RightArm_z" pos="0.0000 0.6203 1.0000" range="-1800.0 1800.0" type="hinge"/>
              <joint axis="1.0000 0.0000 0.0000" name="7_RightArm_x" pos="0.0000 0.6203 1.0000" range="-1800.0 1800.0" type="hinge"/>
              <joint axis="0.0000 1.0000 0.0000" name="7_RightArm_y" pos="0.0000 0.6203 1.0000" range="-1800.0 1800.0" type="hinge"/>
              <geom fromto="-0.0000 0.6403 1.0000 -0.0000 0.8600 1.0000" size="0.0340" type="capsule"/>
              <body name="7_RightForeArm" pos="-0.0000 0.8800 1.0000" user="0.0000 1.1256 1.0000">
                <joint axis="1.0000 0.0000 0.0000" name="7_RightForeArm_x" pos="0.0000 0.8800 1.0000" range="-1800.0 1800.0" type="hinge"/>
                <geom fromto="-0.0000 0.9000 1.0000 -0.0000 1.1056 1.0000" size="0.0300" type="capsule"/>
                <body name="7_RightHand" pos="-0.0000 1.1256 1.0000" user="0.0000 1.1256 1.0000">
                  <geom pos="-0.0000 1.1256 1.0000" size="0.0400" type="sphere"/>
                  <joint axis="0.0000 0.0000 1.0000" name="7_RightHand_z" pos="0.0000 1.1256 1.0000" range="-1800.0 1800.0" type="hinge"/>
                  <joint axis="1.0000 0.0000 0.0000" name="7_RightHand_x" pos="0.0000 1.1256 1.0000" range="-1800.0 1800.0" type="hinge"/>
                  <joint axis="0.0000 1.0000 0.0000" name="7_RightHand_y" pos="0.0000 1.1256 1.0000" range="-1800.0 1800.0" type="hinge"/>
                </body>
              </body>
            </body>
          </body>
        </body>
      </body>
    </body>
    <body name="8_Hips" pos="0.0000 0.0000 1.0000" user="0.0000 0.0003 1.0000">
      <joint armature="0" damping="0" limited="false" name="8_Hips" pos="0.0000 0.0000 1.0000" stiffness="0" type="free"/>
      <geom pos="0.0000 0.0000 0.9780" size="0.0950" type="sphere"/>
      <body name="8_RightUpLeg" pos="-0.1272 0.0000 1.0000" user="-0.1272 -0.4343 1.0000">
        <joint axis="0.0000 0.0000 1.0000" name="8_RightUpLeg_z" pos="-0.1272 0.0000 1.0000" range="-1800.0 1800.0" type="hinge"/>
        <joint axis="1.0000 0.0000 0.0000" name="8_RightUpLeg_x" pos="-0.1272 0.0000 1.0000" range="-1800.0 1800.0" type="hinge"/>
        <joint axis="0.0000 1.0000 0.0000" name="8_RightUpLeg_y" pos="-0.1272 0.0000 1.0000" range="-1800.0 1800.0" type="hinge"/>
        <geom contype="1" conaffinity="1" fromto="-0.1272 -0.0200 1.0000 -0.1272 -0.4143 1.0000" size="0.0490" type="capsule"/>
        <body name="8_RightLeg" pos="-0.1272 -0.4343 1.0000" user="-0.1272 -0.8831 1.0000">
          <joint axis="1.0000 0.0000 0.0000" name="8_RightLeg_x" pos="-0.1272 -0.4343 1.0000" range="-1800.0 1800.0" type="hinge"/>
          <geom contype="1" conaffinity="1" fromto="-0.1272 -0.4543 1.0000 -0.1272 -0.8631 1.0000" size="0.0400" type="capsule"/>
          <body name="8_RightFoot" pos="-0.1272 -0.8831 1.0000" user="-0.1272 -0.8831 1.1515">
            <geom contype="1" conaffinity="1" pos="-0.1272 -0.8831 1.0477" size="0.0620 0.0300 0.1000" quat="0.9952 -0.0871 0.0038 -0.0435" type="box"/>
            <joint axis="0.0000 0.0000 1.0000" name="8_RightFoot_z" pos="-0.1272 -0.8831 1.0000" range="-1800.0 1800.0" type="hinge"/>
            <joint axis="1.0000 0.0000 0.0000" name="8_RightFoot_x" pos="-0.1272 -0.8831 1.0000" range="-1800.0 1800.0" type="hinge"/>
            <joint axis="0.0000 1.0000 0.0000" name="8_RightFoot_y" pos="-0.1272 -0.8831 1.0000" range="-1800.0 1800.0" type="hinge"/>
          </body>
        </body>
      </body>
      <body name="8_LeftUpLeg" pos="0.1272 0.0000 1.0000" user="0.1272 -0.4343 1.0000">
        <joint axis="0.0000 0.0000 1.0000" name="8_LeftUpLeg_z" pos="0.1272 0.0000 1.0000" range="-1800.0 1800.0" type="hinge"/>
        <joint axis="1.0000 0.0000 0.0000" name="8_LeftUpLeg_x" pos="0.1272 0.0000 1.0000" range="-1800.0 1800.0" type="hinge"/>
        <joint axis="0.0000 1.0000 0.0000" name="8_LeftUpLeg_y" pos="0.1272 0.0000 1.0000" range="-1800.0 1800.0" type="hinge"/>
        <geom contype="2" conaffinity="2" fromto="0.1272 -0.0200 1.0000 0.1272 -0.4143 1.0000" size="0.0490" type="capsule"/>
        <body name="8_LeftLeg" pos="0.1272 -0.4343 1.0000" user="0.1272 -0.8831 1.0000">
          <joint axis="1.0000 0.0000 0.0000" name="8_LeftLeg_x" pos="0.1272 -0.4343 1.0000" range="-1800.0 1800.0" type="hinge"/>
          <geom contype="2" conaffinity="2" fromto="0.1272 -0.4543 1.0000 0.1272 -0.8631 1.0000" size="0.0400" type="capsule"/>
          <body name="8_LeftFoot" pos="0.1272 -0.8831 1.0000" user="0.1272 -0.8831 1.1515">
            <geom contype="2" conaffinity="2" pos="0.1272 -0.8831 1.0477" size="0.0620 0.0300 0.1000" quat="0.9952 -0.0871 -0.0038 0.0435" type="box"/>
            <joint axis="0.0000 0.0000 1.0000" name="8_LeftFoot_z" pos="0.1272 -0.8831 1.0000" range="-1800.0 1800.0" type="hinge"/>
            <joint axis="1.0000 0.0000 0.0000" name="8_LeftFoot_x" pos="0.1272 -0.8831 1.0000" range="-1800.0 1800.0" type="hinge"/>
            <joint axis="0.0000 1.0000 0.0000" name="8_LeftFoot_y" pos="0.1272 -0.8831 1.0000" range="-1800.0 1800.0" type="hinge"/>
          </body>
        </body>
      </body>
      <body name="8_Spine" pos="0.0000 0.0010 1.0000" user="0.0000 0.2469 1.0000">
        <geom fromto="-0.0700 0.1240 1.0000 0.0700 0.1240 1.0000" size="0.0450" type="capsule"/>
        <geom fromto="-0.0700 0.2160 1.0000 0.0700 0.2160 1.0000" size="0.0450" type="capsule"/>
        <joint axis="0.0000 0.0000 1.0000" name="8_Spine_z" pos="0.0000 0.0010 1.0000" range="-1800.0 1800.0" type="hinge"/>
        <joint axis="1.0000 0.0000 0.0000" name="8_Spine_x" pos="0.0000 0.0010 1.0000" range="-1800.0 1800.0" type="hinge"/>
        <joint axis="0.0000 1.0000 0.0000" name="8_Spine_y" pos="0.0000 0.0010 1.0000" range="-1800.0 1800.0" type="hinge"/>
        <body name="8_Spine1" pos="0.0000 0.2469 1.0000" user="0.0000 0.4954 1.0000">
          <geom fromto="-0.0700 0.3091 1.0000 0.0700 0.3091 1.0000" size="0.0450" type="capsule"/>
          <geom fromto="-0.0700 0.4011 1.0000 0.0700 0.4011 1.0000" size="0.0450" type="capsule"/>
          <joint axis="0.0000 0.0000 1.0000" name="8_Spine1_z" pos="0.0000 0.2469 1.0000" range="-1800.0 1800.0" type="hinge"/>
          <joint axis="1.0000 0.0000 0.0000" name="8_Spine1_x" pos="0.0000 0.2469 1.0000" range="-1800.0 1800.0" type="hinge"/>
          <joint axis="0.0000 1.0000 0.0000" name="8_Spine1_y" pos="0.0000 0.2469 1.0000" range="-1800.0 1800.0" type="hinge"/>
          <body name="8_Neck" pos="0.0000 0.4954 1.0000" user="0.0000 0.5881 1.0000">
            <joint axis="0.0000 0.0000 1.0000" name="8_Neck_z" pos="0.0000 0.4954 1.0000" range="-1800.0 1800.0" type="hinge"/>
            <joint axis="1.0000 0.0000 0.0000" name="8_Neck_x" pos="0.0000 0.4954 1.0000" range="-1800.0 1800.0" type="hinge"/>
            <joint axis="0.0000 1.0000 0.0000" name="8_Neck_y" pos="0.0000 0.4954 1.0000" range="-1800.0 1800.0" type="hinge"/>
            <geom fromto="0.0000 0.4754 1.0000 0.0000 0.5281 1.0000" size="0.0300" type="capsule"/>
            <body name="8_Head" pos="0.0000 0.5881 1.0000" user="0.0000 0.7031 1.0000">
              <geom pos="0.0000 0.6401 0.9660" size="0.0750" type="sphere"/>
              <joint axis="0.0000 0.0000 1.0000" name="8_Head_z" pos="0.0000 0.5881 1.0000" range="-1800.0 1800.0" type="hinge"/>
              <joint axis="1.0000 0.0000 0.0000" name="8_Head_x" pos="0.0000 0.5881 1.0000" range="-1800.0 1800.0" type="hinge"/>
              <joint axis="0.0000 1.0000 0.0000" name="8_Head_y" pos="0.0000 0.5881 1.0000" range="-1800.0 1800.0" type="hinge"/>
            </body>
          </body>
          <body name="8_LeftShoulder" pos="0.0000 0.4954 1.0000" user="0.0000 0.6203 1.0000">
            <joint axis="0.0000 0.0000 1.0000" name="8_LeftShoulder_z" pos="0.0000 0.4954 1.0000" range="-1800.0 1800.0" type="hinge"/>
            <joint axis="1.0000 0.0000 0.0000" name="8_LeftShoulder_x" pos="0.0000 0.4954 1.0000" range="-1800.0 1800.0" type="hinge"/>
            <joint axis="0.0000 1.0000 0.0000" name="8_LeftShoulder_y" pos="0.0000 0.4954 1.0000" range="-1800.0 1800.0" type="hinge"/>
            <geom fromto="0.0000 0.5154 1.0000 0.0000 0.6003 1.0000" size="0.0400" type="capsule"/>
            <body name="8_LeftArm" pos="0.0000 0.6203 1.0000" user="0.0000 0.8800 1.0000">
              <joint axis="0.0000 0.0000 1.0000" name="8_LeftArm_z" pos="0.0000 0.6203 1.0000" range="-1800.0 1800.0" type="hinge"/>
              <joint axis="1.0000 0.0000 0.0000" name="8_LeftArm_x" pos="0.0000 0.6203 1.0000" range="-1800.0 1800.0" type="hinge"/>
              <joint axis="0.0000 1.0000 0.0000" name="8_LeftArm_y" pos="0.0000 0.6203 1.0000" range="-1800.0 1800.0" type="hinge"/>
              <geom fromto="0.0000 0.6403 1.0000 0.0000 0.8600 1.0000" size="0.0340" type="capsule"/>
              <body name="8_LeftForeArm" pos="0.0000 0.8800 1.0000" user="0.0000 1.1256 1.0000">
                <joint axis="1.0000 0.0000 0.0000" name="8_LeftForeArm_x" pos="0.0000 0.8800 1.0000" range="-1800.0 1800.0" type="hinge"/>
                <geom fromto="0.0000 0.9000 1.0000 0.0000 1.1056 1.0000" size="0.0300" type="capsule"/>
                <body name="8_LeftHand" pos="0.0000 1.1256 1.0000" user="0.0000 1.1256 1.0000">
                  <geom pos="0.0000 1.1256 1.0000" size="0.0400" type="sphere"/>
                  <joint axis="0.0000 0.0000 1.0000" name="8_LeftHand_z" pos="0.0000 1.1256 1.0000" range="-1800.0 1800.0" type="hinge"/>
                  <joint axis="1.0000 0.0000 0.0000" name="8_LeftHand_x" pos="0.0000 1.1256 1.0000" range="-1800.0 1800.0" type="hinge"/>
                  <joint axis="0.0000 1.0000 0.0000" name="8_LeftHand_y" pos="0.0000 1.1256 1.0000" range="-1800.0 1800.0" type="hinge"/>
                </body>
              </body>
            </body>
          </body>
          <body name="8_RightShoulder" pos="-0.0000 0.4954 1.0000" user="0.0000 0.6203 1.0000">
            <joint axis="0.0000 0.0000 1.0000" name="8_RightShoulder_z" pos="0.0000 0.4954 1.0000" range="-1800.0 1800.0" type="hinge"/>
            <joint axis="1.0000 0.0000 0.0000" name="8_RightShoulder_x" pos="0.0000 0.4954 1.0000" range="-1800.0 1800.0" type="hinge"/>
            <joint axis="0.0000 1.0000 0.0000" name="8_RightShoulder_y" pos="0.0000 0.4954 1.0000" range="-1800.0 1800.0" type="hinge"/>
            <geom fromto="-0.0000 0.5154 1.0000 -0.0000 0.6003 1.0000" size="0.0400" type="capsule"/>
            <body name="8_RightArm" pos="-0.0000 0.6203 1.0000" user="0.0000 0.8800 1.0000">
              <joint axis="0.0000 0.0000 1.0000" name="8_RightArm_z" pos="0.0000 0.6203 1.0000" range="-1800.0 1800.0" type="hinge"/>
              <joint axis="1.0000 0.0000 0.0000" name="8_RightArm_x" pos="0.0000 0.6203 1.0000" range="-1800.0 1800.0" type="hinge"/>
              <joint axis="0.0000 1.0000 0.0000" name="8_RightArm_y" pos="0.0000 0.6203 1.0000" range="-1800.0 1800.0" type="hinge"/>
              <geom fromto="-0.0000 0.6403 1.0000 -0.0000 0.8600 1.0000" size="0.0340" type="capsule"/>
              <body name="8_RightForeArm" pos="-0.0000 0.8800 1.0000" user="0.0000 1.1256 1.0000">
                <joint axis="1.0000 0.0000 0.0000" name="8_RightForeArm_x" pos="0.0000 0.8800 1.0000" range="-1800.0 1800.0" type="hinge"/>
                <geom fromto="-0.0000 0.9000 1.0000 -0.0000 1.1056 1.0000" size="0.0300" type="capsule"/>
                <body name="8_RightHand" pos="-0.0000 1.1256 1.0000" user="0.0000 1.1256 1.0000">
                  <geom pos="-0.0000 1.1256 1.0000" size="0.0400" type="sphere"/>
                  <joint axis="0.0000 0.0000 1.0000" name="8_RightHand_z" pos="0.0000 1.1256 1.0000" range="-1800.0 1800.0" type="hinge"/>
                  <joint axis="1.0000 0.0000 0.0000" name="8_RightHand_x" pos="0.0000 1.1256 1.0000" range="-1800.0 1800.0" type="hinge"/>
                  <joint axis="0.0000 1.0000 0.0000" name="8_RightHand_y" pos="0.0000 1.1256 1.0000" range="-1800.0 1800.0" type="hinge"/>
                </body>
              </body>
            </body>
          </body>
        </body>
      </body>
    </body>
    <body name="9_Hips" pos="0.0000 0.0000 1.0000" user="0.0000 0.0003 1.0000">
      <joint armature="0" damping="0" limited="false" name="9_Hips" pos="0.0000 0.0000 1.0000" stiffness="0" type="free"/>
      <geom pos="0.0000 0.0000 0.9780" size="0.0950" type="sphere"/>
      <body name="9_RightUpLeg" pos="-0.1272 0.0000 1.0000" user="-0.1272 -0.4343 1.0000">
        <joint axis="0.0000 0.0000 1.0000" name="9_RightUpLeg_z" pos="-0.1272 0.0000 1.0000" range="-1800.0 1800.0" type="hinge"/>
        <joint axis="1.0000 0.0000 0.0000" name="9_RightUpLeg_x" pos="-0.1272 0.0000 1.0000" range="-1800.0 1800.0" type="hinge"/>
        <joint axis="0.0000 1.0000 0.0000" name="9_RightUpLeg_y" pos="-0.1272 0.0000 1.0000" range="-1800.0 1800.0" type="hinge"/>
        <geom contype="1" conaffinity="1" fromto="-0.1272 -0.0200 1.0000 -0.1272 -0.4143 1.0000" size="0.0490" type="capsule"/>
        <body name="9_RightLeg" pos="-0.1272 -0.4343 1.0000" user="-0.1272 -0.8831 1.0000">
          <joint axis="1.0000 0.0000 0.0000" name="9_RightLeg_x" pos="-0.1272 -0.4343 1.0000" range="-1800.0 1800.0" type="hinge"/>
          <geom contype="1" conaffinity="1" fromto="-0.1272 -0.4543 1.0000 -0.1272 -0.8631 1.0000" size="0.0400" type="capsule"/>
          <body name="9_RightFoot" pos="-0.1272 -0.8831 1.0000" user="-0.1272 -0.8831 1.1515">
            <geom contype="1" conaffinity="1" pos="-0.1272 -0.8831 1.0477" size="0.0620 0.0300 0.1000" quat="0.9952 -0.0871 0.0038 -0.0435" type="box"/>
            <joint axis="0.0000 0.0000 1.0000" name="9_RightFoot_z" pos="-0.1272 -0.8831 1.0000" range="-1800.0 1800.0" type="hinge"/>
            <joint axis="1.0000 0.0000 0.0000" name="9_RightFoot_x" pos="-0.1272 -0.8831 1.0000" range="-1800.0 1800.0" type="hinge"/>
            <joint axis="0.0000 1.0000 0.0000" name="9_RightFoot_y" pos="-0.1272 -0.8831 1.0000" range="-1800.0 1800.0" type="hinge"/>
          </body>
        </body>
      </body>
      <body name="9_LeftUpLeg" pos="0.1272 0.0000 1.0000" user="0.1272 -0.4343 1.0000">
        <joint axis="0.0000 0.0000 1.0000" name="9_LeftUpLeg_z" pos="0.1272 0.0000 1.0000" range="-1800.0 1800.0" type="hinge"/>
        <joint axis="1.0000 0.0000 0.0000" name="9_LeftUpLeg_x" pos="0.1272 0.0000 1.0000" range="-1800.0 1800.0" type="hinge"/>
        <joint axis="0.0000 1.0000 0.0000" name="9_LeftUpLeg_y" pos="0.1272 0.0000 1.0000" range="-1800.0 1800.0" type="hinge"/>
        <geom contype="2" conaffinity="2" fromto="0.1272 -0.0200 1.0000 0.1272 -0.4143 1.0000" size="0.0490" type="capsule"/>
        <body name="9_LeftLeg" pos="0.1272 -0.4343 1.0000" user="0.1272 -0.8831 1.0000">
          <joint axis="1.0000 0.0000 0.0000" name="9_LeftLeg_x" pos="0.1272 -0.4343 1.0000" range="-1800.0 1800.0" type="hinge"/>
          <geom contype="2" conaffinity="2" fromto="0.1272 -0.4543 1.0000 0.1272 -0.8631 1.0000" size="0.0400" type="capsule"/>
          <body name="9_LeftFoot" pos="0.1272 -0.8831 1.0000" user="0.1272 -0.8831 1.1515">
            <geom contype="2" conaffinity="2" pos="0.1272 -0.8831 1.0477" size="0.0620 0.0300 0.1000" quat="0.9952 -0.0871 -0.0038 0.0435" type="box"/>
            <joint axis="0.0000 0.0000 1.0000" name="9_LeftFoot_z" pos="0.1272 -0.8831 1.0000" range="-1800.0 1800.0" type="hinge"/>
            <joint axis="1.0000 0.0000 0.0000" name="9_LeftFoot_x" pos="0.1272 -0.8831 1.0000" range="-1800.0 1800.0" type="hinge"/>
            <joint axis="0.0000 1.0000 0.0000" name="9_LeftFoot_y" pos="0.1272 -0.8831 1.0000" range="-1800.0 1800.0" type="hinge"/>
          </body>
        </body>
      </body>
      <body name="9_Spine" pos="0.0000 0.0010 1.0000" user="0.0000 0.2469 1.0000">
        <geom fromto="-0.0700 0.1240 1.0000 0.0700 0.1240 1.0000" size="0.0450" type="capsule"/>
        <geom fromto="-0.0700 0.2160 1.0000 0.0700 0.2160 1.0000" size="0.0450" type="capsule"/>
        <joint axis="0.0000 0.0000 1.0000" name="9_Spine_z" pos="0.0000 0.0010 1.0000" range="-1800.0 1800.0" type="hinge"/>
        <joint axis="1.0000 0.0000 0.0000" name="9_Spine_x" pos="0.0000 0.0010 1.0000" range="-1800.0 1800.0" type="hinge"/>
        <joint axis="0.0000 1.0000 0.0000" name="9_Spine_y" pos="0.0000 0.0010 1.0000" range="-1800.0 1800.0" type="hinge"/>
        <body name="9_Spine1" pos="0.0000 0.2469 1.0000" user="0.0000 0.4954 1.0000">
          <geom fromto="-0.0700 0.3091 1.0000 0.0700 0.3091 1.0000" size="0.0450" type="capsule"/>
          <geom fromto="-0.0700 0.4011 1.0000 0.0700 0.4011 1.0000" size="0.0450" type="capsule"/>
          <joint axis="0.0000 0.0000 1.0000" name="9_Spine1_z" pos="0.0000 0.2469 1.0000" range="-1800.0 1800.0" type="hinge"/>
          <joint axis="1.0000 0.0000 0.0000" name="9_Spine1_x" pos="0.0000 0.2469 1.0000" range="-1800.0 1800.0" type="hinge"/>
          <joint axis="0.0000 1.0000 0.0000" name="9_Spine1_y" pos="0.0000 0.2469 1.0000" range="-1800.0 1800.0" type="hinge"/>
          <body name="9_Neck" pos="0.0000 0.4954 1.0000" user="0.0000 0.5881 1.0000">
            <joint axis="0.0000 0.0000 1.0000" name="9_Neck_z" pos="0.0000 0.4954 1.0000" range="-1800.0 1800.0" type="hinge"/>
            <joint axis="1.0000 0.0000 0.0000" name="9_Neck_x" pos="0.0000 0.4954 1.0000" range="-1800.0 1800.0" type="hinge"/>
            <joint axis="0.0000 1.0000 0.0000" name="9_Neck_y" pos="0.0000 0.4954 1.0000" range="-1800.0 1800.0" type="hinge"/>
            <geom fromto="0.0000 0.4754 1.0000 0.0000 0.5281 1.0000" size="0.0300" type="capsule"/>
            <body name="9_Head" pos="0.0000 0.5881 1.0000" user="0.0000 0.7031 1.0000">
              <geom pos="0.0000 0.6401 0.9660" size="0.0750" type="sphere"/>
              <joint axis="0.0000 0.0000 1.0000" name="9_Head_z" pos="0.0000 0.5881 1.0000" range="-1800.0 1800.0" type="hinge"/>
              <joint axis="1.0000 0.0000 0.0000" name="9_Head_x" pos="0.0000 0.5881 1.0000" range="-1800.0 1800.0" type="hinge"/>
              <joint axis="0.0000 1.0000 0.0000" name="9_Head_y" pos="0.0000 0.5881 1.0000" range="-1800.0 1800.0" type="hinge"/>
            </body>
          </body>
          <body name="9_LeftShoulder" pos="0.0000 0.4954 1.0000" user="0.0000 0.6203 1.0000">
            <joint axis="0.0000 0.0000 1.0000" name="9_LeftShoulder_z" pos="0.0000 0.4954 1.0000" range="-1800.0 1800.0" type="hinge"/>
            <joint axis="1.0000 0.0000 0.0000" name="9_LeftShoulder_x" pos="0.0000 0.4954 1.0000" range="-1800.0 1800.0" type="hinge"/>
            <joint axis="0.0000 1.0000 0.0000" name="9_LeftShoulder_y" pos="0.0000 0.4954 1.0000" range="-1800.0 1800.0" type="hinge"/>
            <geom fromto="0.0000 0.5154 1.0000 0.0000 0.6003 1.0000" size="0.0400" type="capsule"/>
            <body name="9_LeftArm" pos="0.0000 0.6203 1.0000" user="0.0000 0.8800 1.0000">
              <joint axis="0.0000 0.0000 1.0000" name="9_LeftArm_z" pos="0.0000 0.6203 1.0000" range="-1800.0 1800.0" type="hinge"/>
              <joint axis="1.0000 0.0000 0.0000" name="9_LeftArm_x" pos="0.0000 0.6203 1.0000" range="-1800.0 1800.0" type="hinge"/>
              <joint axis="0.0000 1.0000 0.0000" name="9_LeftArm_y" pos="0.0000 0.6203 1.0000" range="-1800.0 1800.0" type="hinge"/>
              <geom fromto="0.0000 0.6403 1.0000 0.0000 0.8600 1.0000" size="0.0340" type="capsule"/>
              <body name="9_LeftForeArm" pos="0.0000 0.8800 1.0000" user="0.0000 1.1256 1.0000">
                <joint axis="1.0000 0.0000 0.0000" name="9_LeftForeArm_x" pos="0.0000 0.8800 1.0000" range="-1800.0 1800.0" type="hinge"/>
                <geom fromto="0.0000 0.9000 1.0000 0.0000 1.1056 1.0000" size="0.0300" type="capsule"/>
                <body name="9_LeftHand" pos="0.0000 1.1256 1.0000" user="0.0000 1.1256 1.0000">
                  <geom pos="0.0000 1.1256 1.0000" size="0.0400" type="sphere"/>
                  <joint axis="0.0000 0.0000 1.0000" name="9_LeftHand_z" pos="0.0000 1.1256 1.0000" range="-1800.0 1800.0" type="hinge"/>
                  <joint axis="1.0000 0.0000 0.0000" name="9_LeftHand_x" pos="0.0000 1.1256 1.0000" range="-1800.0 1800.0" type="hinge"/>
                  <joint axis="0.0000 1.0000 0.0000" name="9_LeftHand_y" pos="0.0000 1.1256 1.0000" range="-1800.0 1800.0" type="hinge"/>
                </body>
              </body>
            </body>
          </body>
          <body name="9_RightShoulder" pos="-0.0000 0.4954 1.0000" user="0.0000 0.6203 1.0000">
            <joint axis="0.0000 0.0000 1.0000" name="9_RightShoulder_z" pos="0.0000 0.4954 1.0000" range="-1800.0 1800.0" type="hinge"/>
            <joint axis="1.0000 0.0000 0.0000" name="9_RightShoulder_x" pos="0.0000 0.4954 1.0000" range="-1800.0 1800.0" type="hinge"/>
            <joint axis="0.0000 1.0000 0.0000" name="9_RightShoulder_y" pos="0.0000 0.4954 1.0000" range="-1800.0 1800.0" type="hinge"/>
            <geom fromto="-0.0000 0.5154 1.0000 -0.0000 0.6003 1.0000" size="0.0400" type="capsule"/>
            <body name="9_RightArm" pos="-0.0000 0.6203 1.0000" user="0.0000 0.8800 1.0000">
              <joint axis="0.0000 0.0000 1.0000" name="9_RightArm_z" pos="0.0000 0.6203 1.0000" range="-1800.0 1800.0" type="hinge"/>
              <joint axis="1.0000 0.0000 0.0000" name="9_RightArm_x" pos="0.0000 0.6203 1.0000" range="-1800.0 1800.0" type="hinge"/>
              <joint axis="0.0000 1.0000 0.0000" name="9_RightArm_y" pos="0.0000 0.6203 1.0000" range="-1800.0 1800.0" type="hinge"/>
              <geom fromto="-0.0000 0.6403 1.0000 -0.0000 0.8600 1.0000" size="0.0340" type="capsule"/>
              <body name="9_RightForeArm" pos="-0.0000 0.8800 1.0000" user="0.0000 1.1256 1.0000">
                <joint axis="1.0000 0.0000 0.0000" name="9_RightForeArm_x" pos="0.0000 0.8800 1.0000" range="-1800.0 1800.0" type="hinge"/>
                <geom fromto="-0.0000 0.9000 1.0000 -0.0000 1.1056 1.0000" size="0.0300" type="capsule"/>
                <body name="9_RightHand" pos="-0.0000 1.1256 1.0000" user="0.0000 1.1256 1.0000">
                  <geom pos="-0.0000 1.1256 1.0000" size="0.0400" type="sphere"/>
                  <joint axis="0.0000 0.0000 1.0000" name="9_RightHand_z" pos="0.0000 1.1256 1.0000" range="-1800.0 1800.0" type="hinge"/>
                  <joint axis="1.0000 0.0000 0.0000" name="9_RightHand_x" pos="0.0000 1.1256 1.0000" range="-1800.0 1800.0" type="hinge"/>
                  <joint axis="0.0000 1.0000 0.0000" name="9_RightHand_y" pos="0.0000 1.1256 1.0000" range="-1800.0 1800.0" type="hinge"/>
                </body>
              </body>
            </body>
          </body>
        </body>
      </body>
    </body>
  </worldbody>
</mujoco>
